Workbook

Sheet 00_LEIA_ME
B2: NEXA | FP&A INTEGRADO
B6: Projeto | C6: Projeto autoral demonstrativo de Gustavo Xavier. Empresa, operações e resultados integralmente fictícios.
B7: Negócio | C7: Distribuidora B2B de equipamentos tecnológicos: três famílias de produtos, três regiões e dois canais de venda.
B8: Período | C8: 24 meses realizados: jan/2024 a dez/2025. Orçamento dos dois anos. Forecast 2025 com corte em jun/2025 e três cenários para 2026.
B9: Comece aqui | C9: Abra 01_PAINEL. Selecione cenário e ano. DRE, BP, DFC e indicadores mensais acompanham essa seleção.
B10: Planejamento | C10: Premissas em azul na aba 08_PREMISSAS. Forecast 6+6 usa jan–jun realizados e premissas de jul–dez. Os cenários 2026 partem do BP de dez/2025 realizado.
B11: Integração | C11: Receita e CMV → resultado. Clientes, estoque e fornecedores → capital de giro. Capex e depreciação → imobilizado. Lucro → PL. Fluxos → caixa.
B12: Auditoria | C12: 07_CHECKS compara ativo/passivo/PL, DFC direto/indireto e os valores realizados com o diário de partidas dobradas. Tolerância: R$ 0,01.
B13: Base histórica | C13: Vendas, despesas e diário são snapshots fictícios. Alterações no histórico exigem regenerar as bases e o diário com o script; mudanças de planejamento recalculam por fórmulas.
B14: Convenções | C14: DRE: despesas positivas subtraídas nos subtotais. DFC: entradas positivas e saídas negativas. MoM/YoY sem base disponível ficam vazios, nunca zero.
B15: Simplificações | C15: Tributos são premissas pedagógicas; sem créditos tributários, diferidos ou enquadramento fiscal. Juros pagos classificados em operação. Dividendos em financiamento. Receita reconhecida na entrega.
B16: Saldos | C16: Saldo inicial em 31/12/2023 explícito. BP e DFC de orçamento seguem trilha própria; a diferença de dezembro/2024 orçado x realizado é preservada.
B17: Tecnologias | C17: Excel 2021+ sem VBA e sem funções exclusivas do Microsoft 365. CSV UTF-8 e medidas DAX para desenvolver o relatório em Power BI.
B18: Uso comercial | C18: Apresentar como Projeto Autoral. Não atribuir os resultados simulados a clientes ou à experiência profissional anterior.

Sheet 09_VENDAS
A1: Data | B1: ProdutoID | C1: Produto | D1: Regiao | E1: Canal | F1: Quantidade | G1: PrecoUnitario | H1: CustoUnitario | I1: ReceitaBruta | J1: CMV
A2: 45292 | B2: P01 | C2: Estações de trabalho | D2: Sudeste | E2: Venda direta | F2: 83 | G2: 2646.8 | H2: 1820 | I2: 219684.4 | J2: 151060
A3: 45292 | B3: P01 | C3: Estações de trabalho | D3: Sudeste | E3: Parceiros | F3: 46 | G3: 2496 | H3: 1820 | I3: 114816 | J3: 83720
A4: 45292 | B4: P01 | C4: Estações de trabalho | D4: Sul | E4: Venda direta | F4: 37 | G4: 2646.8 | H4: 1820 | I4: 97931.6 | J4: 67340
A5: 45292 | B5: P01 | C5: Estações de trabalho | D5: Sul | E5: Parceiros | F5: 20 | G5: 2496 | H5: 1820 | I5: 49920 | J5: 36400
A6: 45292 | B6: P01 | C6: Estações de trabalho | D6: Nordeste | E6: Venda direta | F6: 26 | G6: 2646.8 | H6: 1820 | I6: 68816.8 | J6: 47320
A7: 45292 | B7: P01 | C7: Estações de trabalho | D7: Nordeste | E7: Parceiros | F7: 15 | G7: 2496 | H7: 1820 | I7: 37440 | J7: 27300
A8: 45292 | B8: P02 | C8: Equipamentos de rede | D8: Sudeste | E8: Venda direta | F8: 60 | G8: 1679.7 | H8: 990 | I8: 100782 | J8: 59400
A9: 45292 | B9: P02 | C9: Equipamentos de rede | D9: Sudeste | E9: Parceiros | F9: 32 | G9: 1584 | H9: 990 | I9: 50688 | J9: 31680
A10: 45292 | B10: P02 | C10: Equipamentos de rede | D10: Sul | E10: Venda direta | F10: 27 | G10: 1679.7 | H10: 990 | I10: 45351.9 | J10: 26730
A11: 45292 | B11: P02 | C11: Equipamentos de rede | D11: Sul | E11: Parceiros | F11: 13 | G11: 1584 | H11: 990 | I11: 20592 | J11: 12870
A12: 45292 | B12: P02 | C12: Equipamentos de rede | D12: Nordeste | E12: Venda direta | F12: 20 | G12: 1679.7 | H12: 990 | I12: 33594 | J12: 19800
A13: 45292 | B13: P02 | C13: Equipamentos de rede | D13: Nordeste | E13: Parceiros | F13: 10 | G13: 1584 | H13: 990 | I13: 15840 | J13: 9900
... A433: 45992 | B433: P03 | C433: Periféricos profissionais | D433: Nordeste | E433: Parceiros | F433: 11 | G433: 682.18 | H433: 399.76 | I433: 7503.98 | J433: 4397.36

Sheet 10_DESPESAS
A1: Data | B1: CentroCusto | C1: Conta | D1: Valor
A2: 45292 | B2: Pessoal | C2: Pessoal | D2: 95000
A3: 45292 | B3: Comercial | C3: Comissões | D3: 33483.76
A4: 45292 | B4: Administrativo | C4: Aluguel e serviços | D4: 32000
A5: 45292 | B5: Tecnologia | C5: Software e infraestrutura | D5: 18000
A6: 45292 | B6: Operações | C6: Logística | D6: 20462.3
A7: 45323 | B7: Pessoal | C7: Pessoal | D7: 95000
A8: 45323 | B8: Comercial | C8: Comissões | D8: 35030.03
A9: 45323 | B9: Administrativo | C9: Aluguel e serviços | D9: 32000
A10: 45323 | B10: Tecnologia | C10: Software e infraestrutura | D10: 18000
A11: 45323 | B11: Operações | C11: Logística | D11: 21407.24
A12: 45352 | B12: Pessoal | C12: Pessoal | D12: 95000
A13: 45352 | B13: Comercial | C13: Comissões | D13: 41009.46
... A123: 45992 | B123: Operações | C123: Logística | D123: 37292.73

Sheet 08_PREMISSAS
A1: Data | B1: Cenario | C1: Quantidade | D1: TicketMedio | E1: CMVPercentual | F1: TaxaComercial | G1: TaxaLogistica | H1: ReceitaBruta | I1: CMV | J1: Pessoal | K1: Comercial | L1: Administrativo | M1: Tecnologia | N1: Logistica | O1: DSO | P1: DIO | Q1: DPO | R1: TaxaVenda | S1: TaxaIR | T1: TaxaJuros | U1: TaxaDep | V1: Capex | W1: Captacao | X1: Amortizacao | Y1: Dividendos
A2: 45292 | B2: Realizado | C2: 499 | D2: 1863.9366 | E2: 0.66156016 | F2: 0.036000002 | G2: 0.022000004 | H2: 930104.38 | I2: 615320 | J2: 95000 | K2: 33483.76 | L2: 32000 | M2: 18000 | N2: 20462.3 | O2: 40 | P2: 46 | Q2: 35 | R2: 0.085 | S2: 0.34 | T2: 0.012 | U2: 0.01 | V2: 18000 | W2: 0 | X2: 18000 | Y2: 0
A3: 45323 | B3: Realizado | C3: 523 | D3: 1860.5286 | E3: 0.66091744 | F3: 0.035999997 | G3: 0.021999997 | H3: 973056.48 | I3: 643110 | J3: 95000 | K3: 35030.03 | L3: 32000 | M3: 18000 | N3: 21407.24 | O3: 40 | P3: 46 | Q3: 35 | R3: 0.085 | S3: 0.34 | T3: 0.012 | U3: 0.01 | V3: 18000 | W3: 0 | X3: 18000 | Y3: 0
A4: 45352 | B4: Realizado | C4: 612 | D4: 1861.3587 | E4: 0.66086905 | F4: 0.036000004 | G4: 0.021999997 | H4: 1139151.5 | I4: 752830 | J4: 95000 | K4: 41009.46 | L4: 32000 | M4: 18000 | N4: 25061.33 | O4: 40 | P4: 46 | Q4: 35 | R4: 0.085 | S4: 0.34 | T4: 0.012 | U4: 0.01 | V4: 90000 | W4: 0 | X4: 18000 | Y4: 0
A5: 45383 | B5: Realizado | C5: 611 | D5: 1865.4973 | E5: 0.66145597 | F5: 0.036 | G5: 0.022000004 | H5: 1139818.9 | I5: 753940 | J5: 95000 | K5: 41033.48 | L5: 32000 | M5: 18000 | N5: 25076.02 | O5: 40 | P5: 46 | Q5: 35 | R5: 0.085 | S5: 0.34 | T5: 0.012 | U5: 0.01 | V5: 18000 | W5: 0 | X5: 18000 | Y5: 0
A6: 45413 | B6: Realizado | C6: 635 | D6: 1867.7797 | E6: 0.66205183 | F6: 0.035999998 | G6: 0.021999999 | H6: 1186040.1 | I6: 785220 | J6: 95000 | K6: 42697.44 | L6: 32000 | M6: 18000 | N6: 26092.88 | O6: 40 | P6: 46 | Q6: 35 | R6: 0.085 | S6: 0.34 | T6: 0.012 | U6: 0.01 | V6: 18000 | W6: 0 | X6: 18000 | Y6: 0
A7: 45444 | B7: Realizado | C7: 654 | D7: 1877.9673 | E7: 0.66190052 | F7: 0.035999999 | G7: 0.021999997 | H7: 1228190.6 | I7: 812940 | J7: 95000 | K7: 44214.86 | L7: 32000 | M7: 18000 | N7: 27020.19 | O7: 40 | P7: 46 | Q7: 35 | R7: 0.085 | S7: 0.34 | T7: 0.012 | U7: 0.01 | V7: 90000 | W7: 0 | X7: 18000 | Y7: 0
A8: 45474 | B8: Realizado | C8: 578 | D8: 1875.1816 | E8: 0.66267169 | F8: 0.036000001 | G8: 0.022000001 | H8: 1083855 | I8: 718240 | J8: 98800 | K8: 39018.78 | L8: 32000 | M8: 18000 | N8: 23844.81 | O8: 40 | P8: 46 | Q8: 35 | R8: 0.085 | S8: 0.34 | T8: 0.012 | U8: 0.01 | V8: 18000 | W8: 0 | X8: 18000 | Y8: 0
A9: 45505 | B9: Realizado | C9: 629 | D9: 1865.5681 | E9: 0.66160047 | F9: 0.035999996 | G9: 0.021999999 | H9: 1173442.3 | I9: 776350 | J9: 98800 | K9: 42243.92 | L9: 32000 | M9: 18000 | N9: 25815.73 | O9: 40 | P9: 46 | Q9: 35 | R9: 0.085 | S9: 0.34 | T9: 0.012 | U9: 0.01 | V9: 18000 | W9: 0 | X9: 18000 | Y9: 0
A10: 45536 | B10: Realizado | C10: 654 | D10: 1863.8934 | E10: 0.66081139 | F10: 0.036000004 | G10: 0.022000002 | H10: 1218986.3 | I10: 805520 | J10: 98800 | K10: 43883.51 | L10: 32000 | M10: 18000 | N10: 26817.7 | O10: 40 | P10: 46 | Q10: 35 | R10: 0.085 | S10: 0.34 | T10: 0.012 | U10: 0.01 | V10: 90000 | W10: 0 | X10: 18000 | Y10: 0
A11: 45566 | B11: Realizado | C11: 707 | D11: 1890.3489 | E11: 0.66251063 | F11: 0.036 | G11: 0.022000003 | H11: 1336476.7 | I11: 885430 | J11: 98800 | K11: 48113.16 | L11: 32000 | M11: 18000 | N11: 29402.49 | O11: 40 | P11: 46 | Q11: 35 | R11: 0.085 | S11: 0.34 | T11: 0.012 | U11: 0.01 | V11: 18000 | W11: 0 | X11: 18000 | Y11: 0
A12: 45597 | B12: Realizado | C12: 800 | D12: 1880.5154 | E12: 0.66223866 | F12: 0.035999998 | G12: 0.021999999 | H12: 1504412.3 | I12: 996280 | J12: 98800 | K12: 54158.84 | L12: 32000 | M12: 18000 | N12: 33097.07 | O12: 40 | P12: 46 | Q12: 35 | R12: 0.085 | S12: 0.34 | T12: 0.012 | U12: 0.01 | V12: 18000 | W12: 0 | X12: 18000 | Y12: 0
A13: 45627 | B13: Realizado | C13: 735 | D13: 1879.8906 | E13: 0.66231239 | F13: 0.035999996 | G13: 0.021999999 | H13: 1381719.6 | I13: 915130 | J13: 98800 | K13: 49741.9 | L13: 32000 | M13: 18000 | N13: 30397.83 | O13: 40 | P13: 46 | Q13: 35 | R13: 0.085 | S13: 0.34 | T13: 0.012 | U13: 0.01 | V13: 90000 | W13: 0 | X13: 18000 | Y13: 0
... A97: 46357 | B97: Adverso 2026 | C97: 897 | D97: 1776.3842 | E97: 0.701 | F97: 0.035 | G97: 0.023 | H97: 1593416.6 | I97: 1116985.1 | J97: 125000 | K97: 55769.58 | L97: 37000 | M97: 24000 | N97: 36648.58 | O97: 65 | P97: 68 | Q97: 30 | R97: 0.085 | S97: 0.34 | T97: 0.012 | U97: 0.01 | V97: 120000 | W97: 0 | X97: 18000 | Y97: 0

Sheet 11_SALDO_INICIAL
A1: Conta | B1: Saldo
A2: CaixaFinal | B2: 3000000
A3: Clientes | B3: 900000
A4: Estoque | B4: 700000
A5: Fornecedores | B5: 550000
A6: SalariosPagar | B6: 40000
A7: TributosVendaPagar | B7: 80000
A8: IRPagar | B8: 50000
A9: ImobilizadoBruto | B9: 1500000
A10: DepAcumulada | B10: 300000
A11: Divida | B11: 800000
A12: Capital | B12: 3900000
A13: LucrosAcumulados | B13: 380000

Sheet 12_MODELO
A1: Data | B1: Cenario | C1: ReceitaBruta | D1: Deducoes | E1: ReceitaLiquida | F1: CMV | G1: LucroBruto | H1: Pessoal | I1: Comercial | J1: Administrativo | K1: Tecnologia | L1: Logistica | M1: Opex | N1: EBITDA | O1: Depreciacao | P1: EBIT | Q1: Juros | R1: LAIR | S1: IRSimulado | T1: LucroLiquido | U1: Clientes | V1: Estoque | W1: Compras | X1: Fornecedores | Y1: SalariosPagar | Z1: TributosVendaPagar | AA1: IRPagar | AB1: Capex | AC1: ImobilizadoBruto | AD1: DepAcumulada | AE1: Captacao | AF1: Amortizacao | AG1: Divida | AH1: Dividendos | AI1: Capital | AJ1: LucrosAcumulados | AK1: Recebimentos | AL1: PagFornecedores | AM1: PagOpex | AN1: PagTributosVenda | AO1: PagIR | AP1: FCO_Direto | AQ1: FCO_Indireto | AR1: FCI | AS1: FCF | AT1: VariacaoCaixa | AU1: CaixaInicial | AV1: CaixaFinal | AW1: Ativo | AX1: Passivo | AY1: PL | AZ1: CheckBP | BA1: CheckDFC | BB1: DSO | BC1: DIO | BD1: DPO | BE1: TaxaVenda | BF1: TaxaIR | BG1: TaxaJuros | BH1: TaxaDep | BI1: MargemEBITDA | BJ1: MargemLiquida | BK1: FC_Livre | BL1: NCG | BM1: DividaLiquida | BN1: CheckDiario | BO1: AtivoCirculante | BP1: AtivoNaoCirculante | BQ1: DividaCP | BR1: DividaLP | BS1: PassivoCirculante | BT1: PassivoNaoCirculante | BU1: LiquidezCorrente
A2: 45292 | B2: Realizado | C2: =SUMIFS('09_VENDAS'!I$2:I$433,'09_VENDAS'!A$2:A$433,'12_MODELO'!A2) -> 930104.38 | D2: ='12_MODELO'!C2*'12_MODELO'!BE2 -> 79058.872 | E2: ='12_MODELO'!C2-'12_MODELO'!D2 -> 851045.51 | F2: =SUMIFS('09_VENDAS'!J$2:J$433,'09_VENDAS'!A$2:A$433,'12_MODELO'!A2) -> 615320 | G2: ='12_MODELO'!E2-'12_MODELO'!F2 -> 235725.51 | H2: =SUMIFS('10_DESPESAS'!D$2:D$123,'10_DESPESAS'!A$2:A$123,'12_MODELO'!A2,'10_DESPESAS'!B$2:B$123,"Pessoal") -> 95000 | I2: =SUMIFS('10_DESPESAS'!D$2:D$123,'10_DESPESAS'!A$2:A$123,'12_MODELO'!A2,'10_DESPESAS'!B$2:B$123,"Comercial") -> 33483.76 | J2: =SUMIFS('10_DESPESAS'!D$2:D$123,'10_DESPESAS'!A$2:A$123,'12_MODELO'!A2,'10_DESPESAS'!B$2:B$123,"Administrativo") -> 32000 | K2: =SUMIFS('10_DESPESAS'!D$2:D$123,'10_DESPESAS'!A$2:A$123,'12_MODELO'!A2,'10_DESPESAS'!B$2:B$123,"Tecnologia") -> 18000 | L2: =SUMIFS('10_DESPESAS'!D$2:D$123,'10_DESPESAS'!A$2:A$123,'12_MODELO'!A2,'10_DESPESAS'!B$2:B$123,"Operações") -> 20462.3 | M2: =SUM('12_MODELO'!H2:'12_MODELO'!L2) -> 198946.06 | N2: ='12_MODELO'!G2-'12_MODELO'!M2 -> 36779.448 | O2: =MIN('11_SALDO_INICIAL'!B9*'12_MODELO'!BH2,'11_SALDO_INICIAL'!B9-'11_SALDO_INICIAL'!B10+'12_MODELO'!AB2) -> 15000 | P2: ='12_MODELO'!N2-'12_MODELO'!O2 -> 21779.448 | Q2: ='11_SALDO_INICIAL'!B11*'12_MODELO'!BG2 -> 9600 | R2: ='12_MODELO'!P2-'12_MODELO'!Q2 -> 12179.448 | S2: =MAX(0,'12_MODELO'!R2)*'12_MODELO'!BF2 -> 4141.0122 | T2: ='12_MODELO'!R2-'12_MODELO'!S2 -> 8038.4355 | U2: ='12_MODELO'!C2*'12_MODELO'!BB2/30 -> 1240139.2 | V2: ='12_MODELO'!F2*'12_MODELO'!BC2/30 -> 943490.67 | W2: ='12_MODELO'!F2+'12_MODELO'!V2-'11_SALDO_INICIAL'!B4 -> 858810.67 | X2: ='12_MODELO'!F2*'12_MODELO'!BD2/30 -> 717873.33 | Y2: ='12_MODELO'!H2*20% -> 19000 | Z2: ='12_MODELO'!D2 -> 79058.872 | AA2: ='12_MODELO'!S2 -> 4141.0122 | AB2: ='08_PREMISSAS'!V2 -> 18000 | AC2: ='11_SALDO_INICIAL'!B9+'12_MODELO'!AB2 -> 1518000 | AD2: ='11_SALDO_INICIAL'!B10+'12_MODELO'!O2 -> 315000 | AE2: ='08_PREMISSAS'!W2 -> 0 | AF2: ='08_PREMISSAS'!X2 -> 18000 | AG2: ='11_SALDO_INICIAL'!B11+'12_MODELO'!AE2-'12_MODELO'!AF2 -> 782000 | AH2: ='08_PREMISSAS'!Y2 -> 0 | AI2: ='11_SALDO_INICIAL'!B12 -> 3900000 | AJ2: ='11_SALDO_INICIAL'!B13+'12_MODELO'!T2-'12_MODELO'!AH2 -> 388038.44 | AK2: ='11_SALDO_INICIAL'!B3+'12_MODELO'!C2-'12_MODELO'!U2 -> 589965.21 | AL2: ='11_SALDO_INICIAL'!B5+'12_MODELO'!W2-'12_MODELO'!X2 -> 690937.33 | AM2: ='12_MODELO'!M2+'11_SALDO_INICIAL'!B6-'12_MODELO'!Y2 -> 219946.06 | AN2: ='11_SALDO_INICIAL'!B7+'12_MODELO'!D2-'12_MODELO'!Z2 -> 80000 | AO2: ='11_SALDO_INICIAL'!B8+'12_MODELO'!S2-'12_MODELO'!AA2 -> 50000 | AP2: ='12_MODELO'!AK2-'12_MODELO'!AL2-'12_MODELO'!AM2-'12_MODELO'!AN2-'12_MODELO'!Q2-'12_MODELO'!AO2 -> -460518.19 | AQ2: ='12_MODELO'!T2+'12_MODELO'!O2-('12_MODELO'!U2-'11_SALDO_INICIAL'!B3)-('12_MODELO'!V2-'11_SALDO_INICIAL'!B4)+('12_MODELO'!X2-'11_SALDO_INICIAL'!B5)+('12_MODELO'!Y2-'11_SALDO_INICIAL'!B6)+('12_MODELO'!Z2-'11_SALDO_INICIAL'!B7)+('12_MODELO'!AA2-'11_SALDO_INICIAL'!B8) -> -460518.19 | AR2: =-'12_MODELO'!AB2 -> -18000 | AS2: ='12_MODELO'!AE2-'12_MODELO'!AF2-'12_MODELO'!AH2 -> -18000 | AT2: ='12_MODELO'!AQ2+'12_MODELO'!AR2+'12_MODELO'!AS2 -> -496518.19 | AU2: ='11_SALDO_INICIAL'!B2 -> 3000000 | AV2: ='12_MODELO'!AU2+'12_MODELO'!AT2 -> 2503481.8 | AW2: ='12_MODELO'!AV2+'12_MODELO'!U2+'12_MODELO'!V2+'12_MODELO'!AC2-'12_MODELO'!AD2 -> 5890111.7 | AX2: ='12_MODELO'!X2+'12_MODELO'!Y2+'12_MODELO'!Z2+'12_MODELO'!AA2+'12_MODELO'!AG2 -> 1602073.2 | AY2: ='12_MODELO'!AI2+'12_MODELO'!AJ2 -> 4288038.4 | AZ2: ='12_MODELO'!AW2-'12_MODELO'!AX2-'12_MODELO'!AY2 -> 0 | BA2: ='12_MODELO'!AP2-'12_MODELO'!AQ2 -> 0 | BB2: ='08_PREMISSAS'!O2 -> 40 | BC2: ='08_PREMISSAS'!P2 -> 46 | BD2: ='08_PREMISSAS'!Q2 -> 35 | BE2: ='08_PREMISSAS'!R2 -> 0.085 | BF2: ='08_PREMISSAS'!S2 -> 0.34 | BG2: ='08_PREMISSAS'!T2 -> 0.012 | BH2: ='08_PREMISSAS'!U2 -> 0.01 | BI2: =IFERROR('12_MODELO'!N2/'12_MODELO'!E2,0) -> 0.043216781 | BJ2: =IFERROR('12_MODELO'!T2/'12_MODELO'!E2,0) -> 0.009445365 | BK2: ='12_MODELO'!AQ2+'12_MODELO'!AR2 -> -478518.19 | BL2: ='12_MODELO'!U2+'12_MODELO'!V2-'12_MODELO'!X2-'12_MODELO'!Y2-'12_MODELO'!Z2-'12_MODELO'!AA2 -> 1363556.6 | BM2: ='12_MODELO'!AG2-'12_MODELO'!AV2 -> -1721481.8 | BN2: =MAX(ABS('15_CONCILIACAO'!F2),ABS('15_CONCILIACAO'!F3),ABS('15_CONCILIACAO'!F4),ABS('15_CONCILIACAO'!F5),ABS('15_CONCILIACAO'!F6),ABS('15_CONCILIACAO'!F7),ABS('15_CONCILIACAO'!F8),ABS('15_CONCILIACAO'!F9),ABS('15_CONCILIACAO'!F10),ABS('15_CONCILIACAO'!F11),ABS('15_CONCILIACAO'!F12),ABS('15_CONCILIACAO'!F13)) -> 4.6566129e-10 | BO2: ='12_MODELO'!AV2+'12_MODELO'!U2+'12_MODELO'!V2 -> 4687111.7 | BP2: ='12_MODELO'!AC2-'12_MODELO'!AD2 -> 1203000 | BQ2: =MIN('12_MODELO'!AG2,'12_MODELO'!AF2*12) -> 216000 | BR2: ='12_MODELO'!AG2-'12_MODELO'!BQ2 -> 566000 | BS2: ='12_MODELO'!AX2-'12_MODELO'!BR2 -> 1036073.2 | BT2: ='12_MODELO'!BR2 -> 566000 | BU2: =IFERROR('12_MODELO'!BO2/'12_MODELO'!BS2,0) -> 4.5239193
A3: 45323 | B3: Realizado | C3: =SUMIFS('09_VENDAS'!I$2:I$433,'09_VENDAS'!A$2:A$433,'12_MODELO'!A3) -> 973056.48 | D3: ='12_MODELO'!C3*'12_MODELO'!BE3 -> 82709.801 | E3: ='12_MODELO'!C3-'12_MODELO'!D3 -> 890346.68 | F3: =SUMIFS('09_VENDAS'!J$2:J$433,'09_VENDAS'!A$2:A$433,'12_MODELO'!A3) -> 643110 | G3: ='12_MODELO'!E3-'12_MODELO'!F3 -> 247236.68 | H3: =SUMIFS('10_DESPESAS'!D$2:D$123,'10_DESPESAS'!A$2:A$123,'12_MODELO'!A3,'10_DESPESAS'!B$2:B$123,"Pessoal") -> 95000 | I3: =SUMIFS('10_DESPESAS'!D$2:D$123,'10_DESPESAS'!A$2:A$123,'12_MODELO'!A3,'10_DESPESAS'!B$2:B$123,"Comercial") -> 35030.03 | J3: =SUMIFS('10_DESPESAS'!D$2:D$123,'10_DESPESAS'!A$2:A$123,'12_MODELO'!A3,'10_DESPESAS'!B$2:B$123,"Administrativo") -> 32000 | K3: =SUMIFS('10_DESPESAS'!D$2:D$123,'10_DESPESAS'!A$2:A$123,'12_MODELO'!A3,'10_DESPESAS'!B$2:B$123,"Tecnologia") -> 18000 | L3: =SUMIFS('10_DESPESAS'!D$2:D$123,'10_DESPESAS'!A$2:A$123,'12_MODELO'!A3,'10_DESPESAS'!B$2:B$123,"Operações") -> 21407.24 | M3: =SUM('12_MODELO'!H3:'12_MODELO'!L3) -> 201437.27 | N3: ='12_MODELO'!G3-'12_MODELO'!M3 -> 45799.409 | O3: =MIN('12_MODELO'!AC2*'12_MODELO'!BH3,'12_MODELO'!AC2-'12_MODELO'!AD2+'12_MODELO'!AB3) -> 15180 | P3: ='12_MODELO'!N3-'12_MODELO'!O3 -> 30619.409 | Q3: ='12_MODELO'!AG2*'12_MODELO'!BG3 -> 9384 | R3: ='12_MODELO'!P3-'12_MODELO'!Q3 -> 21235.409 | S3: =MAX(0,'12_MODELO'!R3)*'12_MODELO'!BF3 -> 7220.0391 | T3: ='12_MODELO'!R3-'12_MODELO'!S3 -> 14015.37 | U3: ='12_MODELO'!C3*'12_MODELO'!BB3/30 -> 1297408.6 | V3: ='12_MODELO'!F3*'12_MODELO'!BC3/30 -> 986102 | W3: ='12_MODELO'!F3+'12_MODELO'!V3-'12_MODELO'!V2 -> 685721.33 | X3: ='12_MODELO'!F3*'12_MODELO'!BD3/30 -> 750295 | Y3: ='12_MODELO'!H3*20% -> 19000 | Z3: ='12_MODELO'!D3 -> 82709.801 | AA3: ='12_MODELO'!S3 -> 7220.0391 | AB3: ='08_PREMISSAS'!V3 -> 18000 | AC3: ='12_MODELO'!AC2+'12_MODELO'!AB3 -> 1536000 | AD3: ='12_MODELO'!AD2+'12_MODELO'!O3 -> 330180 | AE3: ='08_PREMISSAS'!W3 -> 0 | AF3: ='08_PREMISSAS'!X3 -> 18000 | AG3: ='12_MODELO'!AG2+'12_MODELO'!AE3-'12_MODELO'!AF3 -> 764000 | AH3: ='08_PREMISSAS'!Y3 -> 0 | AI3: ='12_MODELO'!AI2 -> 3900000 | AJ3: ='12_MODELO'!AJ2+'12_MODELO'!T3-'12_MODELO'!AH3 -> 402053.81 | AK3: ='12_MODELO'!U2+'12_MODELO'!C3-'12_MODELO'!U3 -> 915787.01 | AL3: ='12_MODELO'!X2+'12_MODELO'!W3-'12_MODELO'!X3 -> 653299.67 | AM3: ='12_MODELO'!M3+'12_MODELO'!Y2-'12_MODELO'!Y3 -> 201437.27 | AN3: ='12_MODELO'!Z2+'12_MODELO'!D3-'12_MODELO'!Z3 -> 79058.872 | AO3: ='12_MODELO'!AA2+'12_MODELO'!S3-'12_MODELO'!AA3 -> 4141.0122 | AP3: ='12_MODELO'!AK3-'12_MODELO'!AL3-'12_MODELO'!AM3-'12_MODELO'!AN3-'12_MODELO'!Q3-'12_MODELO'!AO3 -> -31533.808 | AQ3: ='12_MODELO'!T3+'12_MODELO'!O3-('12_MODELO'!U3-'12_MODELO'!U2)-('12_MODELO'!V3-'12_MODELO'!V2)+('12_MODELO'!X3-'12_MODELO'!X2)+('12_MODELO'!Y3-'12_MODELO'!Y2)+('12_MODELO'!Z3-'12_MODELO'!Z2)+('12_MODELO'!AA3-'12_MODELO'!AA2) -> -31533.808 | AR3: =-'12_MODELO'!AB3 -> -18000 | AS3: ='12_MODELO'!AE3-'12_MODELO'!AF3-'12_MODELO'!AH3 -> -18000 | AT3: ='12_MODELO'!AQ3+'12_MODELO'!AR3+'12_MODELO'!AS3 -> -67533.808 | AU3: ='12_MODELO'!AV2 -> 2503481.8 | AV3: ='12_MODELO'!AU3+'12_MODELO'!AT3 -> 2435948 | AW3: ='12_MODELO'!AV3+'12_MODELO'!U3+'12_MODELO'!V3+'12_MODELO'!AC3-'12_MODELO'!AD3 -> 5925278.6 | AX3: ='12_MODELO'!X3+'12_MODELO'!Y3+'12_MODELO'!Z3+'12_MODELO'!AA3+'12_MODELO'!AG3 -> 1623224.8 | AY3: ='12_MODELO'!AI3+'12_MODELO'!AJ3 -> 4302053.8 | AZ3: ='12_MODELO'!AW3-'12_MODELO'!AX3-'12_MODELO'!AY3 -> 0 | BA3: ='12_MODELO'!AP3-'12_MODELO'!AQ3 -> -5.0931703e-11 | BB3: ='08_PREMISSAS'!O3 -> 40 | BC3: ='08_PREMISSAS'!P3 -> 46 | BD3: ='08_PREMISSAS'!Q3 -> 35 | BE3: ='08_PREMISSAS'!R3 -> 0.085 | BF3: ='08_PREMISSAS'!S3 -> 0.34 | BG3: ='08_PREMISSAS'!T3 -> 0.012 | BH3: ='08_PREMISSAS'!U3 -> 0.01 | BI3: =IFERROR('12_MODELO'!N3/'12_MODELO'!E3,0) -> 0.051439973 | BJ3: =IFERROR('12_MODELO'!T3/'12_MODELO'!E3,0) -> 0.015741475 | BK3: ='12_MODELO'!AQ3+'12_MODELO'!AR3 -> -49533.808 | BL3: ='12_MODELO'!U3+'12_MODELO'!V3-'12_MODELO'!X3-'12_MODELO'!Y3-'12_MODELO'!Z3-'12_MODELO'!AA3 -> 1424285.8 | BM3: ='12_MODELO'!AG3-'12_MODELO'!AV3 -> -1671948 | BN3: =MAX(ABS('15_CONCILIACAO'!F14),ABS('15_CONCILIACAO'!F15),ABS('15_CONCILIACAO'!F16),ABS('15_CONCILIACAO'!F17),ABS('15_CONCILIACAO'!F18),ABS('15_CONCILIACAO'!F19),ABS('15_CONCILIACAO'!F20),ABS('15_CONCILIACAO'!F21),ABS('15_CONCILIACAO'!F22),ABS('15_CONCILIACAO'!F23),ABS('15_CONCILIACAO'!F24),ABS('15_CONCILIACAO'!F25)) -> 9.3132257e-10 | BO3: ='12_MODELO'!AV3+'12_MODELO'!U3+'12_MODELO'!V3 -> 4719458.6 | BP3: ='12_MODELO'!AC3-'12_MODELO'!AD3 -> 1205820 | BQ3: =MIN('12_MODELO'!AG3,'12_MODELO'!AF3*12) -> 216000 | BR3: ='12_MODELO'!AG3-'12_MODELO'!BQ3 -> 548000 | BS3: ='12_MODELO'!AX3-'12_MODELO'!BR3 -> 1075224.8 | BT3: ='12_MODELO'!BR3 -> 548000 | BU3: =IFERROR('12_MODELO'!BO3/'12_MODELO'!BS3,0) -> 4.3892761
A4: 45352 | B4: Realizado | C4: =SUMIFS('09_VENDAS'!I$2:I$433,'09_VENDAS'!A$2:A$433,'12_MODELO'!A4) -> 1139151.5 | D4: ='12_MODELO'!C4*'12_MODELO'!BE4 -> 96827.881 | E4: ='12_MODELO'!C4-'12_MODELO'!D4 -> 1042323.7 | F4: =SUMIFS('09_VENDAS'!J$2:J$433,'09_VENDAS'!A$2:A$433,'12_MODELO'!A4) -> 752830 | G4: ='12_MODELO'!E4-'12_MODELO'!F4 -> 289493.66 | H4: =SUMIFS('10_DESPESAS'!D$2:D$123,'10_DESPESAS'!A$2:A$123,'12_MODELO'!A4,'10_DESPESAS'!B$2:B$123,"Pessoal") -> 95000 | I4: =SUMIFS('10_DESPESAS'!D$2:D$123,'10_DESPESAS'!A$2:A$123,'12_MODELO'!A4,'10_DESPESAS'!B$2:B$123,"Comercial") -> 41009.46 | J4: =SUMIFS('10_DESPESAS'!D$2:D$123,'10_DESPESAS'!A$2:A$123,'12_MODELO'!A4,'10_DESPESAS'!B$2:B$123,"Administrativo") -> 32000 | K4: =SUMIFS('10_DESPESAS'!D$2:D$123,'10_DESPESAS'!A$2:A$123,'12_MODELO'!A4,'10_DESPESAS'!B$2:B$123,"Tecnologia") -> 18000 | L4: =SUMIFS('10_DESPESAS'!D$2:D$123,'10_DESPESAS'!A$2:A$123,'12_MODELO'!A4,'10_DESPESAS'!B$2:B$123,"Operações") -> 25061.33 | M4: =SUM('12_MODELO'!H4:'12_MODELO'!L4) -> 211070.79 | N4: ='12_MODELO'!G4-'12_MODELO'!M4 -> 78422.869 | O4: =MIN('12_MODELO'!AC3*'12_MODELO'!BH4,'12_MODELO'!AC3-'12_MODELO'!AD3+'12_MODELO'!AB4) -> 15360 | P4: ='12_MODELO'!N4-'12_MODELO'!O4 -> 63062.869 | Q4: ='12_MODELO'!AG3*'12_MODELO'!BG4 -> 9168 | R4: ='12_MODELO'!P4-'12_MODELO'!Q4 -> 53894.869 | S4: =MAX(0,'12_MODELO'!R4)*'12_MODELO'!BF4 -> 18324.255 | T4: ='12_MODELO'!R4-'12_MODELO'!S4 -> 35570.614 | U4: ='12_MODELO'!C4*'12_MODELO'!BB4/30 -> 1518868.7 | V4: ='12_MODELO'!F4*'12_MODELO'!BC4/30 -> 1154339.3 | W4: ='12_MODELO'!F4+'12_MODELO'!V4-'12_MODELO'!V3 -> 921067.33 | X4: ='12_MODELO'!F4*'12_MODELO'!BD4/30 -> 878301.67 | Y4: ='12_MODELO'!H4*20% -> 19000 | Z4: ='12_MODELO'!D4 -> 96827.881 | AA4: ='12_MODELO'!S4 -> 18324.255 | AB4: ='08_PREMISSAS'!V4 -> 90000 | AC4: ='12_MODELO'!AC3+'12_MODELO'!AB4 -> 1626000 | AD4: ='12_MODELO'!AD3+'12_MODELO'!O4 -> 345540 | AE4: ='08_PREMISSAS'!W4 -> 0 | AF4: ='08_PREMISSAS'!X4 -> 18000 | AG4: ='12_MODELO'!AG3+'12_MODELO'!AE4-'12_MODELO'!AF4 -> 746000 | AH4: ='08_PREMISSAS'!Y4 -> 0 | AI4: ='12_MODELO'!AI3 -> 3900000 | AJ4: ='12_MODELO'!AJ3+'12_MODELO'!T4-'12_MODELO'!AH4 -> 437624.42 | AK4: ='12_MODELO'!U3+'12_MODELO'!C4-'12_MODELO'!U4 -> 917691.46 | AL4: ='12_MODELO'!X3+'12_MODELO'!W4-'12_MODELO'!X4 -> 793060.67 | AM4: ='12_MODELO'!M4+'12_MODELO'!Y3-'12_MODELO'!Y4 -> 211070.79 | AN4: ='12_MODELO'!Z3+'12_MODELO'!D4-'12_MODELO'!Z4 -> 82709.801 | AO4: ='12_MODELO'!AA3+'12_MODELO'!S4-'12_MODELO'!AA4 -> 7220.0391 | AP4: ='12_MODELO'!AK4-'12_MODELO'!AL4-'12_MODELO'!AM4-'12_MODELO'!AN4-'12_MODELO'!Q4-'12_MODELO'!AO4 -> -185537.84 | AQ4: ='12_MODELO'!T4+'12_MODELO'!O4-('12_MODELO'!U4-'12_MODELO'!U3)-('12_MODELO'!V4-'12_MODELO'!V3)+('12_MODELO'!X4-'12_MODELO'!X3)+('12_MODELO'!Y4-'12_MODELO'!Y3)+('12_MODELO'!Z4-'12_MODELO'!Z3)+('12_MODELO'!AA4-'12_MODELO'!AA3) -> -185537.84 | AR4: =-'12_MODELO'!AB4 -> -90000 | AS4: ='12_MODELO'!AE4-'12_MODELO'!AF4-'12_MODELO'!AH4 -> -18000 | AT4: ='12_MODELO'!AQ4+'12_MODELO'!AR4+'12_MODELO'!AS4 -> -293537.84 | AU4: ='12_MODELO'!AV3 -> 2435948 | AV4: ='12_MODELO'!AU4+'12_MODELO'!AT4 -> 2142410.2 | AW4: ='12_MODELO'!AV4+'12_MODELO'!U4+'12_MODELO'!V4+'12_MODELO'!AC4-'12_MODELO'!AD4 -> 6096078.2 | AX4: ='12_MODELO'!X4+'12_MODELO'!Y4+'12_MODELO'!Z4+'12_MODELO'!AA4+'12_MODELO'!AG4 -> 1758453.8 | AY4: ='12_MODELO'!AI4+'12_MODELO'!AJ4 -> 4337624.4 | AZ4: ='12_MODELO'!AW4-'12_MODELO'!AX4-'12_MODELO'!AY4 -> 0 | BA4: ='12_MODELO'!AP4-'12_MODELO'!AQ4 -> -2.910383e-11 | BB4: ='08_PREMISSAS'!O4 -> 40 | BC4: ='08_PREMISSAS'!P4 -> 46 | BD4: ='08_PREMISSAS'!Q4 -> 35 | BE4: ='08_PREMISSAS'!R4 -> 0.085 | BF4: ='08_PREMISSAS'!S4 -> 0.34 | BG4: ='08_PREMISSAS'!T4 -> 0.012 | BH4: ='08_PREMISSAS'!U4 -> 0.01 | BI4: =IFERROR('12_MODELO'!N4/'12_MODELO'!E4,0) -> 0.0752385 | BJ4: =IFERROR('12_MODELO'!T4/'12_MODELO'!E4,0) -> 0.034126265 | BK4: ='12_MODELO'!AQ4+'12_MODELO'!AR4 -> -275537.84 | BL4: ='12_MODELO'!U4+'12_MODELO'!V4-'12_MODELO'!X4-'12_MODELO'!Y4-'12_MODELO'!Z4-'12_MODELO'!AA4 -> 1660754.3 | BM4: ='12_MODELO'!AG4-'12_MODELO'!AV4 -> -1396410.2 | BN4: =MAX(ABS('15_CONCILIACAO'!F26),ABS('15_CONCILIACAO'!F27),ABS('15_CONCILIACAO'!F28),ABS('15_CONCILIACAO'!F29),ABS('15_CONCILIACAO'!F30),ABS('15_CONCILIACAO'!F31),ABS('15_CONCILIACAO'!F32),ABS('15_CONCILIACAO'!F33),ABS('15_CONCILIACAO'!F34),ABS('15_CONCILIACAO'!F35),ABS('15_CONCILIACAO'!F36),ABS('15_CONCILIACAO'!F37)) -> 1.3969839e-09 | BO4: ='12_MODELO'!AV4+'12_MODELO'!U4+'12_MODELO'!V4 -> 4815618.2 | BP4: ='12_MODELO'!AC4-'12_MODELO'!AD4 -> 1280460 | BQ4: =MIN('12_MODELO'!AG4,'12_MODELO'!AF4*12) -> 216000 | BR4: ='12_MODELO'!AG4-'12_MODELO'!BQ4 -> 530000 | BS4: ='12_MODELO'!AX4-'12_MODELO'!BR4 -> 1228453.8 | BT4: ='12_MODELO'!BR4 -> 530000 | BU4: =IFERROR('12_MODELO'!BO4/'12_MODELO'!BS4,0) -> 3.9200646
A5: 45383 | B5: Realizado | C5: =SUMIFS('09_VENDAS'!I$2:I$433,'09_VENDAS'!A$2:A$433,'12_MODELO'!A5) -> 1139818.9 | D5: ='12_MODELO'!C5*'12_MODELO'!BE5 -> 96884.605 | E5: ='12_MODELO'!C5-'12_MODELO'!D5 -> 1042934.3 | F5: =SUMIFS('09_VENDAS'!J$2:J$433,'09_VENDAS'!A$2:A$433,'12_MODELO'!A5) -> 753940 | G5: ='12_MODELO'!E5-'12_MODELO'!F5 -> 288994.28 | H5: =SUMIFS('10_DESPESAS'!D$2:D$123,'10_DESPESAS'!A$2:A$123,'12_MODELO'!A5,'10_DESPESAS'!B$2:B$123,"Pessoal") -> 95000 | I5: =SUMIFS('10_DESPESAS'!D$2:D$123,'10_DESPESAS'!A$2:A$123,'12_MODELO'!A5,'10_DESPESAS'!B$2:B$123,"Comercial") -> 41033.48 | J5: =SUMIFS('10_DESPESAS'!D$2:D$123,'10_DESPESAS'!A$2:A$123,'12_MODELO'!A5,'10_DESPESAS'!B$2:B$123,"Administrativo") -> 32000 | K5: =SUMIFS('10_DESPESAS'!D$2:D$123,'10_DESPESAS'!A$2:A$123,'12_MODELO'!A5,'10_DESPESAS'!B$2:B$123,"Tecnologia") -> 18000 | L5: =SUMIFS('10_DESPESAS'!D$2:D$123,'10_DESPESAS'!A$2:A$123,'12_MODELO'!A5,'10_DESPESAS'!B$2:B$123,"Operações") -> 25076.02 | M5: =SUM('12_MODELO'!H5:'12_MODELO'!L5) -> 211109.5 | N5: ='12_MODELO'!G5-'12_MODELO'!M5 -> 77884.775 | O5: =MIN('12_MODELO'!AC4*'12_MODELO'!BH5,'12_MODELO'!AC4-'12_MODELO'!AD4+'12_MODELO'!AB5) -> 16260 | P5: ='12_MODELO'!N5-'12_MODELO'!O5 -> 61624.775 | Q5: ='12_MODELO'!AG4*'12_MODELO'!BG5 -> 8952 | R5: ='12_MODELO'!P5-'12_MODELO'!Q5 -> 52672.775 | S5: =MAX(0,'12_MODELO'!R5)*'12_MODELO'!BF5 -> 17908.744 | T5: ='12_MODELO'!R5-'12_MODELO'!S5 -> 34764.032 | U5: ='12_MODELO'!C5*'12_MODELO'!BB5/30 -> 1519758.5 | V5: ='12_MODELO'!F5*'12_MODELO'!BC5/30 -> 1156041.3 | W5: ='12_MODELO'!F5+'12_MODELO'!V5-'12_MODELO'!V4 -> 755642 | X5: ='12_MODELO'!F5*'12_MODELO'!BD5/30 -> 879596.67 | Y5: ='12_MODELO'!H5*20% -> 19000 | Z5: ='12_MODELO'!D5 -> 96884.605 | AA5: ='12_MODELO'!S5 -> 17908.744 | AB5: ='08_PREMISSAS'!V5 -> 18000 | AC5: ='12_MODELO'!AC4+'12_MODELO'!AB5 -> 1644000 | AD5: ='12_MODELO'!AD4+'12_MODELO'!O5 -> 361800 | AE5: ='08_PREMISSAS'!W5 -> 0 | AF5: ='08_PREMISSAS'!X5 -> 18000 | AG5: ='12_MODELO'!AG4+'12_MODELO'!AE5-'12_MODELO'!AF5 -> 728000 | AH5: ='08_PREMISSAS'!Y5 -> 0 | AI5: ='12_MODELO'!AI4 -> 3900000 | AJ5: ='12_MODELO'!AJ4+'12_MODELO'!T5-'12_MODELO'!AH5 -> 472388.45 | AK5: ='12_MODELO'!U4+'12_MODELO'!C5-'12_MODELO'!U5 -> 1138929.1 | AL5: ='12_MODELO'!X4+'12_MODELO'!W5-'12_MODELO'!X5 -> 754347 | AM5: ='12_MODELO'!M5+'12_MODELO'!Y4-'12_MODELO'!Y5 -> 211109.5 | AN5: ='12_MODELO'!Z4+'12_MODELO'!D5-'12_MODELO'!Z5 -> 96827.881 | AO5: ='12_MODELO'!AA4+'12_MODELO'!S5-'12_MODELO'!AA5 -> 18324.255 | AP5: ='12_MODELO'!AK5-'12_MODELO'!AL5-'12_MODELO'!AM5-'12_MODELO'!AN5-'12_MODELO'!Q5-'12_MODELO'!AO5 -> 49368.457 | AQ5: ='12_MODELO'!T5+'12_MODELO'!O5-('12_MODELO'!U5-'12_MODELO'!U4)-('12_MODELO'!V5-'12_MODELO'!V4)+('12_MODELO'!X5-'12_MODELO'!X4)+('12_MODELO'!Y5-'12_MODELO'!Y4)+('12_MODELO'!Z5-'12_MODELO'!Z4)+('12_MODELO'!AA5-'12_MODELO'!AA4) -> 49368.457 | AR5: =-'12_MODELO'!AB5 -> -18000 | AS5: ='12_MODELO'!AE5-'12_MODELO'!AF5-'12_MODELO'!AH5 -> -18000 | AT5: ='12_MODELO'!AQ5+'12_MODELO'!AR5+'12_MODELO'!AS5 -> 13368.457 | AU5: ='12_MODELO'!AV4 -> 2142410.2 | AV5: ='12_MODELO'!AU5+'12_MODELO'!AT5 -> 2155778.6 | AW5: ='12_MODELO'!AV5+'12_MODELO'!U5+'12_MODELO'!V5+'12_MODELO'!AC5-'12_MODELO'!AD5 -> 6113778.5 | AX5: ='12_MODELO'!X5+'12_MODELO'!Y5+'12_MODELO'!Z5+'12_MODELO'!AA5+'12_MODELO'!AG5 -> 1741390 | AY5: ='12_MODELO'!AI5+'12_MODELO'!AJ5 -> 4372388.5 | AZ5: ='12_MODELO'!AW5-'12_MODELO'!AX5-'12_MODELO'!AY5 -> 0 | BA5: ='12_MODELO'!AP5-'12_MODELO'!AQ5 -> -1.5279511e-10 | BB5: ='08_PREMISSAS'!O5 -> 40 | BC5: ='08_PREMISSAS'!P5 -> 46 | BD5: ='08_PREMISSAS'!Q5 -> 35 | BE5: ='08_PREMISSAS'!R5 -> 0.085 | BF5: ='08_PREMISSAS'!S5 -> 0.34 | BG5: ='08_PREMISSAS'!T5 -> 0.012 | BH5: ='08_PREMISSAS'!U5 -> 0.01 | BI5: =IFERROR('12_MODELO'!N5/'12_MODELO'!E5,0) -> 0.074678508 | BJ5: =IFERROR('12_MODELO'!T5/'12_MODELO'!E5,0) -> 0.033332907 | BK5: ='12_MODELO'!AQ5+'12_MODELO'!AR5 -> 31368.457 | BL5: ='12_MODELO'!U5+'12_MODELO'!V5-'12_MODELO'!X5-'12_MODELO'!Y5-'12_MODELO'!Z5-'12_MODELO'!AA5 -> 1662409.8 | BM5: ='12_MODELO'!AG5-'12_MODELO'!AV5 -> -1427778.6 | BN5: =MAX(ABS('15_CONCILIACAO'!F38),ABS('15_CONCILIACAO'!F39),ABS('15_CONCILIACAO'!F40),ABS('15_CONCILIACAO'!F41),ABS('15_CONCILIACAO'!F42),ABS('15_CONCILIACAO'!F43),ABS('15_CONCILIACAO'!F44),ABS('15_CONCILIACAO'!F45),ABS('15_CONCILIACAO'!F46),ABS('15_CONCILIACAO'!F47),ABS('15_CONCILIACAO'!F48),ABS('15_CONCILIACAO'!F49)) -> 9.3132257e-10 | BO5: ='12_MODELO'!AV5+'12_MODELO'!U5+'12_MODELO'!V5 -> 4831578.5 | BP5: ='12_MODELO'!AC5-'12_MODELO'!AD5 -> 1282200 | BQ5: =MIN('12_MODELO'!AG5,'12_MODELO'!AF5*12) -> 216000 | BR5: ='12_MODELO'!AG5-'12_MODELO'!BQ5 -> 512000 | BS5: ='12_MODELO'!AX5-'12_MODELO'!BR5 -> 1229390 | BT5: ='12_MODELO'!BR5 -> 512000 | BU5: =IFERROR('12_MODELO'!BO5/'12_MODELO'!BS5,0) -> 3.9300616
A6: 45413 | B6: Realizado | C6: =SUMIFS('09_VENDAS'!I$2:I$433,'09_VENDAS'!A$2:A$433,'12_MODELO'!A6) -> 1186040.1 | D6: ='12_MODELO'!C6*'12_MODELO'!BE6 -> 100813.41 | E6: ='12_MODELO'!C6-'12_MODELO'!D6 -> 1085226.7 | F6: =SUMIFS('09_VENDAS'!J$2:J$433,'09_VENDAS'!A$2:A$433,'12_MODELO'!A6) -> 785220 | G6: ='12_MODELO'!E6-'12_MODELO'!F6 -> 300006.67 | H6: =SUMIFS('10_DESPESAS'!D$2:D$123,'10_DESPESAS'!A$2:A$123,'12_MODELO'!A6,'10_DESPESAS'!B$2:B$123,"Pessoal") -> 95000 | I6: =SUMIFS('10_DESPESAS'!D$2:D$123,'10_DESPESAS'!A$2:A$123,'12_MODELO'!A6,'10_DESPESAS'!B$2:B$123,"Comercial") -> 42697.44 | J6: =SUMIFS('10_DESPESAS'!D$2:D$123,'10_DESPESAS'!A$2:A$123,'12_MODELO'!A6,'10_DESPESAS'!B$2:B$123,"Administrativo") -> 32000 | K6: =SUMIFS('10_DESPESAS'!D$2:D$123,'10_DESPESAS'!A$2:A$123,'12_MODELO'!A6,'10_DESPESAS'!B$2:B$123,"Tecnologia") -> 18000 | L6: =SUMIFS('10_DESPESAS'!D$2:D$123,'10_DESPESAS'!A$2:A$123,'12_MODELO'!A6,'10_DESPESAS'!B$2:B$123,"Operações") -> 26092.88 | M6: =SUM('12_MODELO'!H6:'12_MODELO'!L6) -> 213790.32 | N6: ='12_MODELO'!G6-'12_MODELO'!M6 -> 86216.353 | O6: =MIN('12_MODELO'!AC5*'12_MODELO'!BH6,'12_MODELO'!AC5-'12_MODELO'!AD5+'12_MODELO'!AB6) -> 16440 | P6: ='12_MODELO'!N6-'12_MODELO'!O6 -> 69776.353 | Q6: ='12_MODELO'!AG5*'12_MODELO'!BG6 -> 8736 | R6: ='12_MODELO'!P6-'12_MODELO'!Q6 -> 61040.353 | S6: =MAX(0,'12_MODELO'!R6)*'12_MODELO'!BF6 -> 20753.72 | T6: ='12_MODELO'!R6-'12_MODELO'!S6 -> 40286.633 | U6: ='12_MODELO'!C6*'12_MODELO'!BB6/30 -> 1581386.8 | V6: ='12_MODELO'!F6*'12_MODELO'!BC6/30 -> 1204004 | W6: ='12_MODELO'!F6+'12_MODELO'!V6-'12_MODELO'!V5 -> 833182.67 | X6: ='12_MODELO'!F6*'12_MODELO'!BD6/30 -> 916090 | Y6: ='12_MODELO'!H6*20% -> 19000 | Z6: ='12_MODELO'!D6 -> 100813.41 | AA6: ='12_MODELO'!S6 -> 20753.72 | AB6: ='08_PREMISSAS'!V6 -> 18000 | AC6: ='12_MODELO'!AC5+'12_MODELO'!AB6 -> 1662000 | AD6: ='12_MODELO'!AD5+'12_MODELO'!O6 -> 378240 | AE6: ='08_PREMISSAS'!W6 -> 0 | AF6: ='08_PREMISSAS'!X6 -> 18000 | AG6: ='12_MODELO'!AG5+'12_MODELO'!AE6-'12_MODELO'!AF6 -> 710000 | AH6: ='08_PREMISSAS'!Y6 -> 0 | AI6: ='12_MODELO'!AI5 -> 3900000 | AJ6: ='12_MODELO'!AJ5+'12_MODELO'!T6-'12_MODELO'!AH6 -> 512675.08 | AK6: ='12_MODELO'!U5+'12_MODELO'!C6-'12_MODELO'!U6 -> 1124411.8 | AL6: ='12_MODELO'!X5+'12_MODELO'!W6-'12_MODELO'!X6 -> 796689.33 | AM6: ='12_MODELO'!M6+'12_MODELO'!Y5-'12_MODELO'!Y6 -> 213790.32 | AN6: ='12_MODELO'!Z5+'12_MODELO'!D6-'12_MODELO'!Z6 -> 96884.605 | AO6: ='12_MODELO'!AA5+'12_MODELO'!S6-'12_MODELO'!AA6 -> 17908.744 | AP6: ='12_MODELO'!AK6-'12_MODELO'!AL6-'12_MODELO'!AM6-'12_MODELO'!AN6-'12_MODELO'!Q6-'12_MODELO'!AO6 -> -9597.1884 | AQ6: ='12_MODELO'!T6+'12_MODELO'!O6-('12_MODELO'!U6-'12_MODELO'!U5)-('12_MODELO'!V6-'12_MODELO'!V5)+('12_MODELO'!X6-'12_MODELO'!X5)+('12_MODELO'!Y6-'12_MODELO'!Y5)+('12_MODELO'!Z6-'12_MODELO'!Z5)+('12_MODELO'!AA6-'12_MODELO'!AA5) -> -9597.1884 | AR6: =-'12_MODELO'!AB6 -> -18000 | AS6: ='12_MODELO'!AE6-'12_MODELO'!AF6-'12_MODELO'!AH6 -> -18000 | AT6: ='12_MODELO'!AQ6+'12_MODELO'!AR6+'12_MODELO'!AS6 -> -45597.188 | AU6: ='12_MODELO'!AV5 -> 2155778.6 | AV6: ='12_MODELO'!AU6+'12_MODELO'!AT6 -> 2110181.4 | AW6: ='12_MODELO'!AV6+'12_MODELO'!U6+'12_MODELO'!V6+'12_MODELO'!AC6-'12_MODELO'!AD6 -> 6179332.2 | AX6: ='12_MODELO'!X6+'12_MODELO'!Y6+'12_MODELO'!Z6+'12_MODELO'!AA6+'12_MODELO'!AG6 -> 1766657.1 | AY6: ='12_MODELO'!AI6+'12_MODELO'!AJ6 -> 4412675.1 | AZ6: ='12_MODELO'!AW6-'12_MODELO'!AX6-'12_MODELO'!AY6 -> 0 | BA6: ='12_MODELO'!AP6-'12_MODELO'!AQ6 -> 8.7311491e-11 | BB6: ='08_PREMISSAS'!O6 -> 40 | BC6: ='08_PREMISSAS'!P6 -> 46 | BD6: ='08_PREMISSAS'!Q6 -> 35 | BE6: ='08_PREMISSAS'!R6 -> 0.085 | BF6: ='08_PREMISSAS'!S6 -> 0.34 | BG6: ='08_PREMISSAS'!T6 -> 0.012 | BH6: ='08_PREMISSAS'!U6 -> 0.01 | BI6: =IFERROR('12_MODELO'!N6/'12_MODELO'!E6,0) -> 0.079445479 | BJ6: =IFERROR('12_MODELO'!T6/'12_MODELO'!E6,0) -> 0.037122782 | BK6: ='12_MODELO'!AQ6+'12_MODELO'!AR6 -> -27597.188 | BL6: ='12_MODELO'!U6+'12_MODELO'!V6-'12_MODELO'!X6-'12_MODELO'!Y6-'12_MODELO'!Z6-'12_MODELO'!AA6 -> 1728733.6 | BM6: ='12_MODELO'!AG6-'12_MODELO'!AV6 -> -1400181.4 | BN6: =MAX(ABS('15_CONCILIACAO'!F50),ABS('15_CONCILIACAO'!F51),ABS('15_CONCILIACAO'!F52),ABS('15_CONCILIACAO'!F53),ABS('15_CONCILIACAO'!F54),ABS('15_CONCILIACAO'!F55),ABS('15_CONCILIACAO'!F56),ABS('15_CONCILIACAO'!F57),ABS('15_CONCILIACAO'!F58),ABS('15_CONCILIACAO'!F59),ABS('15_CONCILIACAO'!F60),ABS('15_CONCILIACAO'!F61)) -> 1.3969839e-09 | BO6: ='12_MODELO'!AV6+'12_MODELO'!U6+'12_MODELO'!V6 -> 4895572.2 | BP6: ='12_MODELO'!AC6-'12_MODELO'!AD6 -> 1283760 | BQ6: =MIN('12_MODELO'!AG6,'12_MODELO'!AF6*12) -> 216000 | BR6: ='12_MODELO'!AG6-'12_MODELO'!BQ6 -> 494000 | BS6: ='12_MODELO'!AX6-'12_MODELO'!BR6 -> 1272657.1 | BT6: ='12_MODELO'!BR6 -> 494000 | BU6: =IFERROR('12_MODELO'!BO6/'12_MODELO'!BS6,0) -> 3.846733
A7: 45444 | B7: Realizado | C7: =SUMIFS('09_VENDAS'!I$2:I$433,'09_VENDAS'!A$2:A$433,'12_MODELO'!A7) -> 1228190.6 | D7: ='12_MODELO'!C7*'12_MODELO'!BE7 -> 104396.2 | E7: ='12_MODELO'!C7-'12_MODELO'!D7 -> 1123794.4 | F7: =SUMIFS('09_VENDAS'!J$2:J$433,'09_VENDAS'!A$2:A$433,'12_MODELO'!A7) -> 812940 | G7: ='12_MODELO'!E7-'12_MODELO'!F7 -> 310854.4 | H7: =SUMIFS('10_DESPESAS'!D$2:D$123,'10_DESPESAS'!A$2:A$123,'12_MODELO'!A7,'10_DESPESAS'!B$2:B$123,"Pessoal") -> 95000 | I7: =SUMIFS('10_DESPESAS'!D$2:D$123,'10_DESPESAS'!A$2:A$123,'12_MODELO'!A7,'10_DESPESAS'!B$2:B$123,"Comercial") -> 44214.86 | J7: =SUMIFS('10_DESPESAS'!D$2:D$123,'10_DESPESAS'!A$2:A$123,'12_MODELO'!A7,'10_DESPESAS'!B$2:B$123,"Administrativo") -> 32000 | K7: =SUMIFS('10_DESPESAS'!D$2:D$123,'10_DESPESAS'!A$2:A$123,'12_MODELO'!A7,'10_DESPESAS'!B$2:B$123,"Tecnologia") -> 18000 | L7: =SUMIFS('10_DESPESAS'!D$2:D$123,'10_DESPESAS'!A$2:A$123,'12_MODELO'!A7,'10_DESPESAS'!B$2:B$123,"Operações") -> 27020.19 | M7: =SUM('12_MODELO'!H7:'12_MODELO'!L7) -> 216235.05 | N7: ='12_MODELO'!G7-'12_MODELO'!M7 -> 94619.349 | O7: =MIN('12_MODELO'!AC6*'12_MODELO'!BH7,'12_MODELO'!AC6-'12_MODELO'!AD6+'12_MODELO'!AB7) -> 16620 | P7: ='12_MODELO'!N7-'12_MODELO'!O7 -> 77999.349 | Q7: ='12_MODELO'!AG6*'12_MODELO'!BG7 -> 8520 | R7: ='12_MODELO'!P7-'12_MODELO'!Q7 -> 69479.349 | S7: =MAX(0,'12_MODELO'!R7)*'12_MODELO'!BF7 -> 23622.979 | T7: ='12_MODELO'!R7-'12_MODELO'!S7 -> 45856.37 | U7: ='12_MODELO'!C7*'12_MODELO'!BB7/30 -> 1637587.5 | V7: ='12_MODELO'!F7*'12_MODELO'!BC7/30 -> 1246508 | W7: ='12_MODELO'!F7+'12_MODELO'!V7-'12_MODELO'!V6 -> 855444 | X7: ='12_MODELO'!F7*'12_MODELO'!BD7/30 -> 948430 | Y7: ='12_MODELO'!H7*20% -> 19000 | Z7: ='12_MODELO'!D7 -> 104396.2 | AA7: ='12_MODELO'!S7 -> 23622.979 | AB7: ='08_PREMISSAS'!V7 -> 90000 | AC7: ='12_MODELO'!AC6+'12_MODELO'!AB7 -> 1752000 | AD7: ='12_MODELO'!AD6+'12_MODELO'!O7 -> 394860 | AE7: ='08_PREMISSAS'!W7 -> 0 | AF7: ='08_PREMISSAS'!X7 -> 18000 | AG7: ='12_MODELO'!AG6+'12_MODELO'!AE7-'12_MODELO'!AF7 -> 692000 | AH7: ='08_PREMISSAS'!Y7 -> 0 | AI7: ='12_MODELO'!AI6 -> 3900000 | AJ7: ='12_MODELO'!AJ6+'12_MODELO'!T7-'12_MODELO'!AH7 -> 558531.45 | AK7: ='12_MODELO'!U6+'12_MODELO'!C7-'12_MODELO'!U7 -> 1171989.9 | AL7: ='12_MODELO'!X6+'12_MODELO'!W7-'12_MODELO'!X7 -> 823104 | AM7: ='12_MODELO'!M7+'12_MODELO'!Y6-'12_MODELO'!Y7 -> 216235.05 | AN7: ='12_MODELO'!Z6+'12_MODELO'!D7-'12_MODELO'!Z7 -> 100813.41 | AO7: ='12_MODELO'!AA6+'12_MODELO'!S7-'12_MODELO'!AA7 -> 20753.72 | AP7: ='12_MODELO'!AK7-'12_MODELO'!AL7-'12_MODELO'!AM7-'12_MODELO'!AN7-'12_MODELO'!Q7-'12_MODELO'!AO7 -> 2563.7298 | AQ7: ='12_MODELO'!T7+'12_MODELO'!O7-('12_MODELO'!U7-'12_MODELO'!U6)-('12_MODELO'!V7-'12_MODELO'!V6)+('12_MODELO'!X7-'12_MODELO'!X6)+('12_MODELO'!Y7-'12_MODELO'!Y6)+('12_MODELO'!Z7-'12_MODELO'!Z6)+('12_MODELO'!AA7-'12_MODELO'!AA6) -> 2563.7298 | AR7: =-'12_MODELO'!AB7 -> -90000 | AS7: ='12_MODELO'!AE7-'12_MODELO'!AF7-'12_MODELO'!AH7 -> -18000 | AT7: ='12_MODELO'!AQ7+'12_MODELO'!AR7+'12_MODELO'!AS7 -> -105436.27 | AU7: ='12_MODELO'!AV6 -> 2110181.4 | AV7: ='12_MODELO'!AU7+'12_MODELO'!AT7 -> 2004745.2 | AW7: ='12_MODELO'!AV7+'12_MODELO'!U7+'12_MODELO'!V7+'12_MODELO'!AC7-'12_MODELO'!AD7 -> 6245980.6 | AX7: ='12_MODELO'!X7+'12_MODELO'!Y7+'12_MODELO'!Z7+'12_MODELO'!AA7+'12_MODELO'!AG7 -> 1787449.2 | AY7: ='12_MODELO'!AI7+'12_MODELO'!AJ7 -> 4458531.5 | AZ7: ='12_MODELO'!AW7-'12_MODELO'!AX7-'12_MODELO'!AY7 -> 0 | BA7: ='12_MODELO'!AP7-'12_MODELO'!AQ7 -> 9.094947e-11 | BB7: ='08_PREMISSAS'!O7 -> 40 | BC7: ='08_PREMISSAS'!P7 -> 46 | BD7: ='08_PREMISSAS'!Q7 -> 35 | BE7: ='08_PREMISSAS'!R7 -> 0.085 | BF7: ='08_PREMISSAS'!S7 -> 0.34 | BG7: ='08_PREMISSAS'!T7 -> 0.012 | BH7: ='08_PREMISSAS'!U7 -> 0.01 | BI7: =IFERROR('12_MODELO'!N7/'12_MODELO'!E7,0) -> 0.084196317 | BJ7: =IFERROR('12_MODELO'!T7/'12_MODELO'!E7,0) -> 0.040804947 | BK7: ='12_MODELO'!AQ7+'12_MODELO'!AR7 -> -87436.27 | BL7: ='12_MODELO'!U7+'12_MODELO'!V7-'12_MODELO'!X7-'12_MODELO'!Y7-'12_MODELO'!Z7-'12_MODELO'!AA7 -> 1788646.3 | BM7: ='12_MODELO'!AG7-'12_MODELO'!AV7 -> -1312745.2 | BN7: =MAX(ABS('15_CONCILIACAO'!F62),ABS('15_CONCILIACAO'!F63),ABS('15_CONCILIACAO'!F64),ABS('15_CONCILIACAO'!F65),ABS('15_CONCILIACAO'!F66),ABS('15_CONCILIACAO'!F67),ABS('15_CONCILIACAO'!F68),ABS('15_CONCILIACAO'!F69),ABS('15_CONCILIACAO'!F70),ABS('15_CONCILIACAO'!F71),ABS('15_CONCILIACAO'!F72),ABS('15_CONCILIACAO'!F73)) -> 1.6298145e-09 | BO7: ='12_MODELO'!AV7+'12_MODELO'!U7+'12_MODELO'!V7 -> 4888840.6 | BP7: ='12_MODELO'!AC7-'12_MODELO'!AD7 -> 1357140 | BQ7: =MIN('12_MODELO'!AG7,'12_MODELO'!AF7*12) -> 216000 | BR7: ='12_MODELO'!AG7-'12_MODELO'!BQ7 -> 476000 | BS7: ='12_MODELO'!AX7-'12_MODELO'!BR7 -> 1311449.2 | BT7: ='12_MODELO'!BR7 -> 476000 | BU7: =IFERROR('12_MODELO'!BO7/'12_MODELO'!BS7,0) -> 3.7278155
A8: 45474 | B8: Realizado | C8: =SUMIFS('09_VENDAS'!I$2:I$433,'09_VENDAS'!A$2:A$433,'12_MODELO'!A8) -> 1083855 | D8: ='12_MODELO'!C8*'12_MODELO'!BE8 -> 92127.672 | E8: ='12_MODELO'!C8-'12_MODELO'!D8 -> 991727.29 | F8: =SUMIFS('09_VENDAS'!J$2:J$433,'09_VENDAS'!A$2:A$433,'12_MODELO'!A8) -> 718240 | G8: ='12_MODELO'!E8-'12_MODELO'!F8 -> 273487.29 | H8: =SUMIFS('10_DESPESAS'!D$2:D$123,'10_DESPESAS'!A$2:A$123,'12_MODELO'!A8,'10_DESPESAS'!B$2:B$123,"Pessoal") -> 98800 | I8: =SUMIFS('10_DESPESAS'!D$2:D$123,'10_DESPESAS'!A$2:A$123,'12_MODELO'!A8,'10_DESPESAS'!B$2:B$123,"Comercial") -> 39018.78 | J8: =SUMIFS('10_DESPESAS'!D$2:D$123,'10_DESPESAS'!A$2:A$123,'12_MODELO'!A8,'10_DESPESAS'!B$2:B$123,"Administrativo") -> 32000 | K8: =SUMIFS('10_DESPESAS'!D$2:D$123,'10_DESPESAS'!A$2:A$123,'12_MODELO'!A8,'10_DESPESAS'!B$2:B$123,"Tecnologia") -> 18000 | L8: =SUMIFS('10_DESPESAS'!D$2:D$123,'10_DESPESAS'!A$2:A$123,'12_MODELO'!A8,'10_DESPESAS'!B$2:B$123,"Operações") -> 23844.81 | M8: =SUM('12_MODELO'!H8:'12_MODELO'!L8) -> 211663.59 | N8: ='12_MODELO'!G8-'12_MODELO'!M8 -> 61823.698 | O8: =MIN('12_MODELO'!AC7*'12_MODELO'!BH8,'12_MODELO'!AC7-'12_MODELO'!AD7+'12_MODELO'!AB8) -> 17520 | P8: ='12_MODELO'!N8-'12_MODELO'!O8 -> 44303.698 | Q8: ='12_MODELO'!AG7*'12_MODELO'!BG8 -> 8304 | R8: ='12_MODELO'!P8-'12_MODELO'!Q8 -> 35999.698 | S8: =MAX(0,'12_MODELO'!R8)*'12_MODELO'!BF8 -> 12239.897 | T8: ='12_MODELO'!R8-'12_MODELO'!S8 -> 23759.801 | U8: ='12_MODELO'!C8*'12_MODELO'!BB8/30 -> 1445139.9 | V8: ='12_MODELO'!F8*'12_MODELO'!BC8/30 -> 1101301.3 | W8: ='12_MODELO'!F8+'12_MODELO'!V8-'12_MODELO'!V7 -> 573033.33 | X8: ='12_MODELO'!F8*'12_MODELO'!BD8/30 -> 837946.67 | Y8: ='12_MODELO'!H8*20% -> 19760 | Z8: ='12_MODELO'!D8 -> 92127.672 | AA8: ='12_MODELO'!S8 -> 12239.897 | AB8: ='08_PREMISSAS'!V8 -> 18000 | AC8: ='12_MODELO'!AC7+'12_MODELO'!AB8 -> 1770000 | AD8: ='12_MODELO'!AD7+'12_MODELO'!O8 -> 412380 | AE8: ='08_PREMISSAS'!W8 -> 0 | AF8: ='08_PREMISSAS'!X8 -> 18000 | AG8: ='12_MODELO'!AG7+'12_MODELO'!AE8-'12_MODELO'!AF8 -> 674000 | AH8: ='08_PREMISSAS'!Y8 -> 0 | AI8: ='12_MODELO'!AI7 -> 3900000 | AJ8: ='12_MODELO'!AJ7+'12_MODELO'!T8-'12_MODELO'!AH8 -> 582291.26 | AK8: ='12_MODELO'!U7+'12_MODELO'!C8-'12_MODELO'!U8 -> 1276302.5 | AL8: ='12_MODELO'!X7+'12_MODELO'!W8-'12_MODELO'!X8 -> 683516.67 | AM8: ='12_MODELO'!M8+'12_MODELO'!Y7-'12_MODELO'!Y8 -> 210903.59 | AN8: ='12_MODELO'!Z7+'12_MODELO'!D8-'12_MODELO'!Z8 -> 104396.2 | AO8: ='12_MODELO'!AA7+'12_MODELO'!S8-'12_MODELO'!AA8 -> 23622.979 | AP8: ='12_MODELO'!AK8-'12_MODELO'!AL8-'12_MODELO'!AM8-'12_MODELO'!AN8-'12_MODELO'!Q8-'12_MODELO'!AO8 -> 245559.04 | AQ8: ='12_MODELO'!T8+'12_MODELO'!O8-('12_MODELO'!U8-'12_MODELO'!U7)-('12_MODELO'!V8-'12_MODELO'!V7)+('12_MODELO'!X8-'12_MODELO'!X7)+('12_MODELO'!Y8-'12_MODELO'!Y7)+('12_MODELO'!Z8-'12_MODELO'!Z7)+('12_MODELO'!AA8-'12_MODELO'!AA7) -> 245559.04 | AR8: =-'12_MODELO'!AB8 -> -18000 | AS8: ='12_MODELO'!AE8-'12_MODELO'!AF8-'12_MODELO'!AH8 -> -18000 | AT8: ='12_MODELO'!AQ8+'12_MODELO'!AR8+'12_MODELO'!AS8 -> 209559.04 | AU8: ='12_MODELO'!AV7 -> 2004745.2 | AV8: ='12_MODELO'!AU8+'12_MODELO'!AT8 -> 2214304.2 | AW8: ='12_MODELO'!AV8+'12_MODELO'!U8+'12_MODELO'!V8+'12_MODELO'!AC8-'12_MODELO'!AD8 -> 6118365.5 | AX8: ='12_MODELO'!X8+'12_MODELO'!Y8+'12_MODELO'!Z8+'12_MODELO'!AA8+'12_MODELO'!AG8 -> 1636074.2 | AY8: ='12_MODELO'!AI8+'12_MODELO'!AJ8 -> 4482291.3 | AZ8: ='12_MODELO'!AW8-'12_MODELO'!AX8-'12_MODELO'!AY8 -> -9.3132257e-10 | BA8: ='12_MODELO'!AP8-'12_MODELO'!AQ8 -> 2.910383e-10 | BB8: ='08_PREMISSAS'!O8 -> 40 | BC8: ='08_PREMISSAS'!P8 -> 46 | BD8: ='08_PREMISSAS'!Q8 -> 35 | BE8: ='08_PREMISSAS'!R8 -> 0.085 | BF8: ='08_PREMISSAS'!S8 -> 0.34 | BG8: ='08_PREMISSAS'!T8 -> 0.012 | BH8: ='08_PREMISSAS'!U8 -> 0.01 | BI8: =IFERROR('12_MODELO'!N8/'12_MODELO'!E8,0) -> 0.062339414 | BJ8: =IFERROR('12_MODELO'!T8/'12_MODELO'!E8,0) -> 0.023957999 | BK8: ='12_MODELO'!AQ8+'12_MODELO'!AR8 -> 227559.04 | BL8: ='12_MODELO'!U8+'12_MODELO'!V8-'12_MODELO'!X8-'12_MODELO'!Y8-'12_MODELO'!Z8-'12_MODELO'!AA8 -> 1584367 | BM8: ='12_MODELO'!AG8-'12_MODELO'!AV8 -> -1540304.2 | BN8: =MAX(ABS('15_CONCILIACAO'!F74),ABS('15_CONCILIACAO'!F75),ABS('15_CONCILIACAO'!F76),ABS('15_CONCILIACAO'!F77),ABS('15_CONCILIACAO'!F78),ABS('15_CONCILIACAO'!F79),ABS('15_CONCILIACAO'!F80),ABS('15_CONCILIACAO'!F81),ABS('15_CONCILIACAO'!F82),ABS('15_CONCILIACAO'!F83),ABS('15_CONCILIACAO'!F84),ABS('15_CONCILIACAO'!F85)) -> 1.8626451e-09 | BO8: ='12_MODELO'!AV8+'12_MODELO'!U8+'12_MODELO'!V8 -> 4760745.5 | BP8: ='12_MODELO'!AC8-'12_MODELO'!AD8 -> 1357620 | BQ8: =MIN('12_MODELO'!AG8,'12_MODELO'!AF8*12) -> 216000 | BR8: ='12_MODELO'!AG8-'12_MODELO'!BQ8 -> 458000 | BS8: ='12_MODELO'!AX8-'12_MODELO'!BR8 -> 1178074.2 | BT8: ='12_MODELO'!BR8 -> 458000 | BU8: =IFERROR('12_MODELO'!BO8/'12_MODELO'!BS8,0) -> 4.0411252
A9: 45505 | B9: Realizado | C9: =SUMIFS('09_VENDAS'!I$2:I$433,'09_VENDAS'!A$2:A$433,'12_MODELO'!A9) -> 1173442.3 | D9: ='12_MODELO'!C9*'12_MODELO'!BE9 -> 99742.599 | E9: ='12_MODELO'!C9-'12_MODELO'!D9 -> 1073699.7 | F9: =SUMIFS('09_VENDAS'!J$2:J$433,'09_VENDAS'!A$2:A$433,'12_MODELO'!A9) -> 776350 | G9: ='12_MODELO'!E9-'12_MODELO'!F9 -> 297349.74 | H9: =SUMIFS('10_DESPESAS'!D$2:D$123,'10_DESPESAS'!A$2:A$123,'12_MODELO'!A9,'10_DESPESAS'!B$2:B$123,"Pessoal") -> 98800 | I9: =SUMIFS('10_DESPESAS'!D$2:D$123,'10_DESPESAS'!A$2:A$123,'12_MODELO'!A9,'10_DESPESAS'!B$2:B$123,"Comercial") -> 42243.92 | J9: =SUMIFS('10_DESPESAS'!D$2:D$123,'10_DESPESAS'!A$2:A$123,'12_MODELO'!A9,'10_DESPESAS'!B$2:B$123,"Administrativo") -> 32000 | K9: =SUMIFS('10_DESPESAS'!D$2:D$123,'10_DESPESAS'!A$2:A$123,'12_MODELO'!A9,'10_DESPESAS'!B$2:B$123,"Tecnologia") -> 18000 | L9: =SUMIFS('10_DESPESAS'!D$2:D$123,'10_DESPESAS'!A$2:A$123,'12_MODELO'!A9,'10_DESPESAS'!B$2:B$123,"Operações") -> 25815.73 | M9: =SUM('12_MODELO'!H9:'12_MODELO'!L9) -> 216859.65 | N9: ='12_MODELO'!G9-'12_MODELO'!M9 -> 80490.091 | O9: =MIN('12_MODELO'!AC8*'12_MODELO'!BH9,'12_MODELO'!AC8-'12_MODELO'!AD8+'12_MODELO'!AB9) -> 17700 | P9: ='12_MODELO'!N9-'12_MODELO'!O9 -> 62790.091 | Q9: ='12_MODELO'!AG8*'12_MODELO'!BG9 -> 8088 | R9: ='12_MODELO'!P9-'12_MODELO'!Q9 -> 54702.091 | S9: =MAX(0,'12_MODELO'!R9)*'12_MODELO'!BF9 -> 18598.711 | T9: ='12_MODELO'!R9-'12_MODELO'!S9 -> 36103.38 | U9: ='12_MODELO'!C9*'12_MODELO'!BB9/30 -> 1564589.8 | V9: ='12_MODELO'!F9*'12_MODELO'!BC9/30 -> 1190403.3 | W9: ='12_MODELO'!F9+'12_MODELO'!V9-'12_MODELO'!V8 -> 865452 | X9: ='12_MODELO'!F9*'12_MODELO'!BD9/30 -> 905741.67 | Y9: ='12_MODELO'!H9*20% -> 19760 | Z9: ='12_MODELO'!D9 -> 99742.599 | AA9: ='12_MODELO'!S9 -> 18598.711 | AB9: ='08_PREMISSAS'!V9 -> 18000 | AC9: ='12_MODELO'!AC8+'12_MODELO'!AB9 -> 1788000 | AD9: ='12_MODELO'!AD8+'12_MODELO'!O9 -> 430080 | AE9: ='08_PREMISSAS'!W9 -> 0 | AF9: ='08_PREMISSAS'!X9 -> 18000 | AG9: ='12_MODELO'!AG8+'12_MODELO'!AE9-'12_MODELO'!AF9 -> 656000 | AH9: ='08_PREMISSAS'!Y9 -> 0 | AI9: ='12_MODELO'!AI8 -> 3900000 | AJ9: ='12_MODELO'!AJ8+'12_MODELO'!T9-'12_MODELO'!AH9 -> 618394.64 | AK9: ='12_MODELO'!U8+'12_MODELO'!C9-'12_MODELO'!U9 -> 1053992.5 | AL9: ='12_MODELO'!X8+'12_MODELO'!W9-'12_MODELO'!X9 -> 797657 | AM9: ='12_MODELO'!M9+'12_MODELO'!Y8-'12_MODELO'!Y9 -> 216859.65 | AN9: ='12_MODELO'!Z8+'12_MODELO'!D9-'12_MODELO'!Z9 -> 92127.672 | AO9: ='12_MODELO'!AA8+'12_MODELO'!S9-'12_MODELO'!AA9 -> 12239.897 | AP9: ='12_MODELO'!AK9-'12_MODELO'!AL9-'12_MODELO'!AM9-'12_MODELO'!AN9-'12_MODELO'!Q9-'12_MODELO'!AO9 -> -72979.719 | AQ9: ='12_MODELO'!T9+'12_MODELO'!O9-('12_MODELO'!U9-'12_MODELO'!U8)-('12_MODELO'!V9-'12_MODELO'!V8)+('12_MODELO'!X9-'12_MODELO'!X8)+('12_MODELO'!Y9-'12_MODELO'!Y8)+('12_MODELO'!Z9-'12_MODELO'!Z8)+('12_MODELO'!AA9-'12_MODELO'!AA8) -> -72979.719 | AR9: =-'12_MODELO'!AB9 -> -18000 | AS9: ='12_MODELO'!AE9-'12_MODELO'!AF9-'12_MODELO'!AH9 -> -18000 | AT9: ='12_MODELO'!AQ9+'12_MODELO'!AR9+'12_MODELO'!AS9 -> -108979.72 | AU9: ='12_MODELO'!AV8 -> 2214304.2 | AV9: ='12_MODELO'!AU9+'12_MODELO'!AT9 -> 2105324.5 | AW9: ='12_MODELO'!AV9+'12_MODELO'!U9+'12_MODELO'!V9+'12_MODELO'!AC9-'12_MODELO'!AD9 -> 6218237.6 | AX9: ='12_MODELO'!X9+'12_MODELO'!Y9+'12_MODELO'!Z9+'12_MODELO'!AA9+'12_MODELO'!AG9 -> 1699843 | AY9: ='12_MODELO'!AI9+'12_MODELO'!AJ9 -> 4518394.6 | AZ9: ='12_MODELO'!AW9-'12_MODELO'!AX9-'12_MODELO'!AY9 -> 9.3132257e-10 | BA9: ='12_MODELO'!AP9-'12_MODELO'!AQ9 -> 2.1827873e-10 | BB9: ='08_PREMISSAS'!O9 -> 40 | BC9: ='08_PREMISSAS'!P9 -> 46 | BD9: ='08_PREMISSAS'!Q9 -> 35 | BE9: ='08_PREMISSAS'!R9 -> 0.085 | BF9: ='08_PREMISSAS'!S9 -> 0.34 | BG9: ='08_PREMISSAS'!T9 -> 0.012 | BH9: ='08_PREMISSAS'!U9 -> 0.01 | BI9: =IFERROR('12_MODELO'!N9/'12_MODELO'!E9,0) -> 0.074965177 | BJ9: =IFERROR('12_MODELO'!T9/'12_MODELO'!E9,0) -> 0.033625211 | BK9: ='12_MODELO'!AQ9+'12_MODELO'!AR9 -> -90979.719 | BL9: ='12_MODELO'!U9+'12_MODELO'!V9-'12_MODELO'!X9-'12_MODELO'!Y9-'12_MODELO'!Z9-'12_MODELO'!AA9 -> 1711150.1 | BM9: ='12_MODELO'!AG9-'12_MODELO'!AV9 -> -1449324.5 | BN9: =MAX(ABS('15_CONCILIACAO'!F86),ABS('15_CONCILIACAO'!F87),ABS('15_CONCILIACAO'!F88),ABS('15_CONCILIACAO'!F89),ABS('15_CONCILIACAO'!F90),ABS('15_CONCILIACAO'!F91),ABS('15_CONCILIACAO'!F92),ABS('15_CONCILIACAO'!F93),ABS('15_CONCILIACAO'!F94),ABS('15_CONCILIACAO'!F95),ABS('15_CONCILIACAO'!F96),ABS('15_CONCILIACAO'!F97)) -> 1.8626451e-09 | BO9: ='12_MODELO'!AV9+'12_MODELO'!U9+'12_MODELO'!V9 -> 4860317.6 | BP9: ='12_MODELO'!AC9-'12_MODELO'!AD9 -> 1357920 | BQ9: =MIN('12_MODELO'!AG9,'12_MODELO'!AF9*12) -> 216000 | BR9: ='12_MODELO'!AG9-'12_MODELO'!BQ9 -> 440000 | BS9: ='12_MODELO'!AX9-'12_MODELO'!BR9 -> 1259843 | BT9: ='12_MODELO'!BR9 -> 440000 | BU9: =IFERROR('12_MODELO'!BO9/'12_MODELO'!BS9,0) -> 3.8578757
A10: 45536 | B10: Realizado | C10: =SUMIFS('09_VENDAS'!I$2:I$433,'09_VENDAS'!A$2:A$433,'12_MODELO'!A10) -> 1218986.3 | D10: ='12_MODELO'!C10*'12_MODELO'!BE10 -> 103613.83 | E10: ='12_MODELO'!C10-'12_MODELO'!D10 -> 1115372.4 | F10: =SUMIFS('09_VENDAS'!J$2:J$433,'09_VENDAS'!A$2:A$433,'12_MODELO'!A10) -> 805520 | G10: ='12_MODELO'!E10-'12_MODELO'!F10 -> 309852.43 | H10: =SUMIFS('10_DESPESAS'!D$2:D$123,'10_DESPESAS'!A$2:A$123,'12_MODELO'!A10,'10_DESPESAS'!B$2:B$123,"Pessoal") -> 98800 | I10: =SUMIFS('10_DESPESAS'!D$2:D$123,'10_DESPESAS'!A$2:A$123,'12_MODELO'!A10,'10_DESPESAS'!B$2:B$123,"Comercial") -> 43883.51 | J10: =SUMIFS('10_DESPESAS'!D$2:D$123,'10_DESPESAS'!A$2:A$123,'12_MODELO'!A10,'10_DESPESAS'!B$2:B$123,"Administrativo") -> 32000 | K10: =SUMIFS('10_DESPESAS'!D$2:D$123,'10_DESPESAS'!A$2:A$123,'12_MODELO'!A10,'10_DESPESAS'!B$2:B$123,"Tecnologia") -> 18000 | L10: =SUMIFS('10_DESPESAS'!D$2:D$123,'10_DESPESAS'!A$2:A$123,'12_MODELO'!A10,'10_DESPESAS'!B$2:B$123,"Operações") -> 26817.7 | M10: =SUM('12_MODELO'!H10:'12_MODELO'!L10) -> 219501.21 | N10: ='12_MODELO'!G10-'12_MODELO'!M10 -> 90351.218 | O10: =MIN('12_MODELO'!AC9*'12_MODELO'!BH10,'12_MODELO'!AC9-'12_MODELO'!AD9+'12_MODELO'!AB10) -> 17880 | P10: ='12_MODELO'!N10-'12_MODELO'!O10 -> 72471.218 | Q10: ='12_MODELO'!AG9*'12_MODELO'!BG10 -> 7872 | R10: ='12_MODELO'!P10-'12_MODELO'!Q10 -> 64599.218 | S10: =MAX(0,'12_MODELO'!R10)*'12_MODELO'!BF10 -> 21963.734 | T10: ='12_MODELO'!R10-'12_MODELO'!S10 -> 42635.484 | U10: ='12_MODELO'!C10*'12_MODELO'!BB10/30 -> 1625315 | V10: ='12_MODELO'!F10*'12_MODELO'!BC10/30 -> 1235130.7 | W10: ='12_MODELO'!F10+'12_MODELO'!V10-'12_MODELO'!V9 -> 850247.33 | X10: ='12_MODELO'!F10*'12_MODELO'!BD10/30 -> 939773.33 | Y10: ='12_MODELO'!H10*20% -> 19760 | Z10: ='12_MODELO'!D10 -> 103613.83 | AA10: ='12_MODELO'!S10 -> 21963.734 | AB10: ='08_PREMISSAS'!V10 -> 90000 | AC10: ='12_MODELO'!AC9+'12_MODELO'!AB10 -> 1878000 | AD10: ='12_MODELO'!AD9+'12_MODELO'!O10 -> 447960 | AE10: ='08_PREMISSAS'!W10 -> 0 | AF10: ='08_PREMISSAS'!X10 -> 18000 | AG10: ='12_MODELO'!AG9+'12_MODELO'!AE10-'12_MODELO'!AF10 -> 638000 | AH10: ='08_PREMISSAS'!Y10 -> 0 | AI10: ='12_MODELO'!AI9 -> 3900000 | AJ10: ='12_MODELO'!AJ9+'12_MODELO'!T10-'12_MODELO'!AH10 -> 661030.12 | AK10: ='12_MODELO'!U9+'12_MODELO'!C10-'12_MODELO'!U10 -> 1158261 | AL10: ='12_MODELO'!X9+'12_MODELO'!W10-'12_MODELO'!X10 -> 816215.67 | AM10: ='12_MODELO'!M10+'12_MODELO'!Y9-'12_MODELO'!Y10 -> 219501.21 | AN10: ='12_MODELO'!Z9+'12_MODELO'!D10-'12_MODELO'!Z10 -> 99742.599 | AO10: ='12_MODELO'!AA9+'12_MODELO'!S10-'12_MODELO'!AA10 -> 18598.711 | AP10: ='12_MODELO'!AK10-'12_MODELO'!AL10-'12_MODELO'!AM10-'12_MODELO'!AN10-'12_MODELO'!Q10-'12_MODELO'!AO10 -> -3669.1532 | AQ10: ='12_MODELO'!T10+'12_MODELO'!O10-('12_MODELO'!U10-'12_MODELO'!U9)-('12_MODELO'!V10-'12_MODELO'!V9)+('12_MODELO'!X10-'12_MODELO'!X9)+('12_MODELO'!Y10-'12_MODELO'!Y9)+('12_MODELO'!Z10-'12_MODELO'!Z9)+('12_MODELO'!AA10-'12_MODELO'!AA9) -> -3669.1532 | AR10: =-'12_MODELO'!AB10 -> -90000 | AS10: ='12_MODELO'!AE10-'12_MODELO'!AF10-'12_MODELO'!AH10 -> -18000 | AT10: ='12_MODELO'!AQ10+'12_MODELO'!AR10+'12_MODELO'!AS10 -> -111669.15 | AU10: ='12_MODELO'!AV9 -> 2105324.5 | AV10: ='12_MODELO'!AU10+'12_MODELO'!AT10 -> 1993655.3 | AW10: ='12_MODELO'!AV10+'12_MODELO'!U10+'12_MODELO'!V10+'12_MODELO'!AC10-'12_MODELO'!AD10 -> 6284141 | AX10: ='12_MODELO'!X10+'12_MODELO'!Y10+'12_MODELO'!Z10+'12_MODELO'!AA10+'12_MODELO'!AG10 -> 1723110.9 | AY10: ='12_MODELO'!AI10+'12_MODELO'!AJ10 -> 4561030.1 | AZ10: ='12_MODELO'!AW10-'12_MODELO'!AX10-'12_MODELO'!AY10 -> 0 | BA10: ='12_MODELO'!AP10-'12_MODELO'!AQ10 -> 3.2378011e-10 | BB10: ='08_PREMISSAS'!O10 -> 40 | BC10: ='08_PREMISSAS'!P10 -> 46 | BD10: ='08_PREMISSAS'!Q10 -> 35 | BE10: ='08_PREMISSAS'!R10 -> 0.085 | BF10: ='08_PREMISSAS'!S10 -> 0.34 | BG10: ='08_PREMISSAS'!T10 -> 0.012 | BH10: ='08_PREMISSAS'!U10 -> 0.01 | BI10: =IFERROR('12_MODELO'!N10/'12_MODELO'!E10,0) -> 0.081005425 | BJ10: =IFERROR('12_MODELO'!T10/'12_MODELO'!E10,0) -> 0.038225334 | BK10: ='12_MODELO'!AQ10+'12_MODELO'!AR10 -> -93669.153 | BL10: ='12_MODELO'!U10+'12_MODELO'!V10-'12_MODELO'!X10-'12_MODELO'!Y10-'12_MODELO'!Z10-'12_MODELO'!AA10 -> 1775334.8 | BM10: ='12_MODELO'!AG10-'12_MODELO'!AV10 -> -1355655.3 | BN10: =MAX(ABS('15_CONCILIACAO'!F98),ABS('15_CONCILIACAO'!F99),ABS('15_CONCILIACAO'!F100),ABS('15_CONCILIACAO'!F101),ABS('15_CONCILIACAO'!F102),ABS('15_CONCILIACAO'!F103),ABS('15_CONCILIACAO'!F104),ABS('15_CONCILIACAO'!F105),ABS('15_CONCILIACAO'!F106),ABS('15_CONCILIACAO'!F107),ABS('15_CONCILIACAO'!F108),ABS('15_CONCILIACAO'!F109)) -> 2.3283064e-09 | BO10: ='12_MODELO'!AV10+'12_MODELO'!U10+'12_MODELO'!V10 -> 4854101 | BP10: ='12_MODELO'!AC10-'12_MODELO'!AD10 -> 1430040 | BQ10: =MIN('12_MODELO'!AG10,'12_MODELO'!AF10*12) -> 216000 | BR10: ='12_MODELO'!AG10-'12_MODELO'!BQ10 -> 422000 | BS10: ='12_MODELO'!AX10-'12_MODELO'!BR10 -> 1301110.9 | BT10: ='12_MODELO'!BR10 -> 422000 | BU10: =IFERROR('12_MODELO'!BO10/'12_MODELO'!BS10,0) -> 3.7307358
A11: 45566 | B11: Realizado | C11: =SUMIFS('09_VENDAS'!I$2:I$433,'09_VENDAS'!A$2:A$433,'12_MODELO'!A11) -> 1336476.7 | D11: ='12_MODELO'!C11*'12_MODELO'!BE11 -> 113600.52 | E11: ='12_MODELO'!C11-'12_MODELO'!D11 -> 1222876.1 | F11: =SUMIFS('09_VENDAS'!J$2:J$433,'09_VENDAS'!A$2:A$433,'12_MODELO'!A11) -> 885430 | G11: ='12_MODELO'!E11-'12_MODELO'!F11 -> 337446.14 | H11: =SUMIFS('10_DESPESAS'!D$2:D$123,'10_DESPESAS'!A$2:A$123,'12_MODELO'!A11,'10_DESPESAS'!B$2:B$123,"Pessoal") -> 98800 | I11: =SUMIFS('10_DESPESAS'!D$2:D$123,'10_DESPESAS'!A$2:A$123,'12_MODELO'!A11,'10_DESPESAS'!B$2:B$123,"Comercial") -> 48113.16 | J11: =SUMIFS('10_DESPESAS'!D$2:D$123,'10_DESPESAS'!A$2:A$123,'12_MODELO'!A11,'10_DESPESAS'!B$2:B$123,"Administrativo") -> 32000 | K11: =SUMIFS('10_DESPESAS'!D$2:D$123,'10_DESPESAS'!A$2:A$123,'12_MODELO'!A11,'10_DESPESAS'!B$2:B$123,"Tecnologia") -> 18000 | L11: =SUMIFS('10_DESPESAS'!D$2:D$123,'10_DESPESAS'!A$2:A$123,'12_MODELO'!A11,'10_DESPESAS'!B$2:B$123,"Operações") -> 29402.49 | M11: =SUM('12_MODELO'!H11:'12_MODELO'!L11) -> 226315.65 | N11: ='12_MODELO'!G11-'12_MODELO'!M11 -> 111130.49 | O11: =MIN('12_MODELO'!AC10*'12_MODELO'!BH11,'12_MODELO'!AC10-'12_MODELO'!AD10+'12_MODELO'!AB11) -> 18780 | P11: ='12_MODELO'!N11-'12_MODELO'!O11 -> 92350.494 | Q11: ='12_MODELO'!AG10*'12_MODELO'!BG11 -> 7656 | R11: ='12_MODELO'!P11-'12_MODELO'!Q11 -> 84694.494 | S11: =MAX(0,'12_MODELO'!R11)*'12_MODELO'!BF11 -> 28796.128 | T11: ='12_MODELO'!R11-'12_MODELO'!S11 -> 55898.366 | U11: ='12_MODELO'!C11*'12_MODELO'!BB11/30 -> 1781968.9 | V11: ='12_MODELO'!F11*'12_MODELO'!BC11/30 -> 1357659.3 | W11: ='12_MODELO'!F11+'12_MODELO'!V11-'12_MODELO'!V10 -> 1007958.7 | X11: ='12_MODELO'!F11*'12_MODELO'!BD11/30 -> 1033001.7 | Y11: ='12_MODELO'!H11*20% -> 19760 | Z11: ='12_MODELO'!D11 -> 113600.52 | AA11: ='12_MODELO'!S11 -> 28796.128 | AB11: ='08_PREMISSAS'!V11 -> 18000 | AC11: ='12_MODELO'!AC10+'12_MODELO'!AB11 -> 1896000 | AD11: ='12_MODELO'!AD10+'12_MODELO'!O11 -> 466740 | AE11: ='08_PREMISSAS'!W11 -> 0 | AF11: ='08_PREMISSAS'!X11 -> 18000 | AG11: ='12_MODELO'!AG10+'12_MODELO'!AE11-'12_MODELO'!AF11 -> 620000 | AH11: ='08_PREMISSAS'!Y11 -> 0 | AI11: ='12_MODELO'!AI10 -> 3900000 | AJ11: ='12_MODELO'!AJ10+'12_MODELO'!T11-'12_MODELO'!AH11 -> 716928.49 | AK11: ='12_MODELO'!U10+'12_MODELO'!C11-'12_MODELO'!U11 -> 1179822.8 | AL11: ='12_MODELO'!X10+'12_MODELO'!W11-'12_MODELO'!X11 -> 914730.33 | AM11: ='12_MODELO'!M11+'12_MODELO'!Y10-'12_MODELO'!Y11 -> 226315.65 | AN11: ='12_MODELO'!Z10+'12_MODELO'!D11-'12_MODELO'!Z11 -> 103613.83 | AO11: ='12_MODELO'!AA10+'12_MODELO'!S11-'12_MODELO'!AA11 -> 21963.734 | AP11: ='12_MODELO'!AK11-'12_MODELO'!AL11-'12_MODELO'!AM11-'12_MODELO'!AN11-'12_MODELO'!Q11-'12_MODELO'!AO11 -> -94456.756 | AQ11: ='12_MODELO'!T11+'12_MODELO'!O11-('12_MODELO'!U11-'12_MODELO'!U10)-('12_MODELO'!V11-'12_MODELO'!V10)+('12_MODELO'!X11-'12_MODELO'!X10)+('12_MODELO'!Y11-'12_MODELO'!Y10)+('12_MODELO'!Z11-'12_MODELO'!Z10)+('12_MODELO'!AA11-'12_MODELO'!AA10) -> -94456.756 | AR11: =-'12_MODELO'!AB11 -> -18000 | AS11: ='12_MODELO'!AE11-'12_MODELO'!AF11-'12_MODELO'!AH11 -> -18000 | AT11: ='12_MODELO'!AQ11+'12_MODELO'!AR11+'12_MODELO'!AS11 -> -130456.76 | AU11: ='12_MODELO'!AV10 -> 1993655.3 | AV11: ='12_MODELO'!AU11+'12_MODELO'!AT11 -> 1863198.6 | AW11: ='12_MODELO'!AV11+'12_MODELO'!U11+'12_MODELO'!V11+'12_MODELO'!AC11-'12_MODELO'!AD11 -> 6432086.8 | AX11: ='12_MODELO'!X11+'12_MODELO'!Y11+'12_MODELO'!Z11+'12_MODELO'!AA11+'12_MODELO'!AG11 -> 1815158.3 | AY11: ='12_MODELO'!AI11+'12_MODELO'!AJ11 -> 4616928.5 | AZ11: ='12_MODELO'!AW11-'12_MODELO'!AX11-'12_MODELO'!AY11 -> 0 | BA11: ='12_MODELO'!AP11-'12_MODELO'!AQ11 -> 1.4551915e-11 | BB11: ='08_PREMISSAS'!O11 -> 40 | BC11: ='08_PREMISSAS'!P11 -> 46 | BD11: ='08_PREMISSAS'!Q11 -> 35 | BE11: ='08_PREMISSAS'!R11 -> 0.085 | BF11: ='08_PREMISSAS'!S11 -> 0.34 | BG11: ='08_PREMISSAS'!T11 -> 0.012 | BH11: ='08_PREMISSAS'!U11 -> 0.01 | BI11: =IFERROR('12_MODELO'!N11/'12_MODELO'!E11,0) -> 0.090876328 | BJ11: =IFERROR('12_MODELO'!T11/'12_MODELO'!E11,0) -> 0.04571057 | BK11: ='12_MODELO'!AQ11+'12_MODELO'!AR11 -> -112456.76 | BL11: ='12_MODELO'!U11+'12_MODELO'!V11-'12_MODELO'!X11-'12_MODELO'!Y11-'12_MODELO'!Z11-'12_MODELO'!AA11 -> 1944469.9 | BM11: ='12_MODELO'!AG11-'12_MODELO'!AV11 -> -1243198.6 | BN11: =MAX(ABS('15_CONCILIACAO'!F110),ABS('15_CONCILIACAO'!F111),ABS('15_CONCILIACAO'!F112),ABS('15_CONCILIACAO'!F113),ABS('15_CONCILIACAO'!F114),ABS('15_CONCILIACAO'!F115),ABS('15_CONCILIACAO'!F116),ABS('15_CONCILIACAO'!F117),ABS('15_CONCILIACAO'!F118),ABS('15_CONCILIACAO'!F119),ABS('15_CONCILIACAO'!F120),ABS('15_CONCILIACAO'!F121)) -> 2.3283064e-09 | BO11: ='12_MODELO'!AV11+'12_MODELO'!U11+'12_MODELO'!V11 -> 5002826.8 | BP11: ='12_MODELO'!AC11-'12_MODELO'!AD11 -> 1429260 | BQ11: =MIN('12_MODELO'!AG11,'12_MODELO'!AF11*12) -> 216000 | BR11: ='12_MODELO'!AG11-'12_MODELO'!BQ11 -> 404000 | BS11: ='12_MODELO'!AX11-'12_MODELO'!BR11 -> 1411158.3 | BT11: ='12_MODELO'!BR11 -> 404000 | BU11: =IFERROR('12_MODELO'!BO11/'12_MODELO'!BS11,0) -> 3.5451917
